[2023-04-15 23:54:44,635] {taskinstance.py:903} INFO - Dependencies all met for <TaskInstance: processing_dag.processing_task 2023-04-15T23:54:41.804118+00:00 [queued]>
[2023-04-15 23:54:44,667] {taskinstance.py:903} INFO - Dependencies all met for <TaskInstance: processing_dag.processing_task 2023-04-15T23:54:41.804118+00:00 [queued]>
[2023-04-15 23:54:44,667] {taskinstance.py:1095} INFO - 
--------------------------------------------------------------------------------
[2023-04-15 23:54:44,667] {taskinstance.py:1096} INFO - Starting attempt 1 of 1
[2023-04-15 23:54:44,667] {taskinstance.py:1097} INFO - 
--------------------------------------------------------------------------------
[2023-04-15 23:54:44,686] {taskinstance.py:1115} INFO - Executing <Task(PythonOperator): processing_task> on 2023-04-15T23:54:41.804118+00:00
[2023-04-15 23:54:44,690] {standard_task_runner.py:52} INFO - Started process 56 to run task
[2023-04-15 23:54:44,695] {standard_task_runner.py:76} INFO - Running: ['***', 'tasks', 'run', 'processing_dag', 'processing_task', '2023-04-15T23:54:41.804118+00:00', '--job-id', '4', '--pool', 'default_pool', '--raw', '--subdir', 'DAGS_FOLDER/mining_etl.py', '--cfg-path', '/tmp/tmpyojtj321', '--error-file', '/tmp/tmp2yb5gpp7']
[2023-04-15 23:54:44,695] {standard_task_runner.py:77} INFO - Job 4: Subtask processing_task
[2023-04-15 23:54:44,750] {logging_mixin.py:109} INFO - Running <TaskInstance: processing_dag.processing_task 2023-04-15T23:54:41.804118+00:00 [running]> on host d1ce0343a975
[2023-04-15 23:54:44,864] {taskinstance.py:1254} INFO - Exporting the following env vars:
AIRFLOW_CTX_DAG_OWNER=***
AIRFLOW_CTX_DAG_ID=processing_dag
AIRFLOW_CTX_TASK_ID=processing_task
AIRFLOW_CTX_EXECUTION_DATE=2023-04-15T23:54:41.804118+00:00
AIRFLOW_CTX_DAG_RUN_ID=manual__2023-04-15T23:54:41.804118+00:00
[2023-04-15 23:54:44,865] {taskinstance.py:1463} ERROR - Task failed with exception
Traceback (most recent call last):
  File "/home/airflow/.local/lib/python3.6/site-packages/airflow/models/taskinstance.py", line 1165, in _run_raw_task
    self._prepare_and_execute_task_with_callbacks(context, task)
  File "/home/airflow/.local/lib/python3.6/site-packages/airflow/models/taskinstance.py", line 1283, in _prepare_and_execute_task_with_callbacks
    result = self._execute_task(context, task_copy)
  File "/home/airflow/.local/lib/python3.6/site-packages/airflow/models/taskinstance.py", line 1313, in _execute_task
    result = task_copy.execute(context=context)
  File "/home/airflow/.local/lib/python3.6/site-packages/airflow/operators/python.py", line 150, in execute
    return_value = self.execute_callable()
  File "/home/airflow/.local/lib/python3.6/site-packages/airflow/operators/python.py", line 161, in execute_callable
    return self.python_callable(*self.op_args, **self.op_kwargs)
  File "/opt/airflow/dags/mining_etl.py", line 11, in process
    file = pd.read_csv(csv)
NameError: name 'csv' is not defined
[2023-04-15 23:54:44,867] {taskinstance.py:1513} INFO - Marking task as FAILED. dag_id=processing_dag, task_id=processing_task, execution_date=20230415T235441, start_date=20230415T235444, end_date=20230415T235444
[2023-04-15 23:54:44,947] {local_task_job.py:151} INFO - Task exited with return code 1
[2023-04-15 23:54:44,986] {local_task_job.py:261} INFO - 0 downstream tasks scheduled from follow-on schedule check
