[2023-04-15 23:19:44,751] {processor.py:162} INFO - Started process (PID=97) to work on /opt/airflow/dags/mining_etl.py
[2023-04-15 23:19:44,752] {processor.py:613} INFO - Processing file /opt/airflow/dags/mining_etl.py for tasks to queue
[2023-04-15 23:19:44,752] {logging_mixin.py:109} INFO - [2023-04-15 23:19:44,752] {dagbag.py:496} INFO - Filling up the DagBag from /opt/airflow/dags/mining_etl.py
[2023-04-15 23:19:44,755] {logging_mixin.py:109} INFO - [2023-04-15 23:19:44,754] {dagbag.py:329} ERROR - Failed to import: /opt/airflow/dags/mining_etl.py
Traceback (most recent call last):
  File "/home/airflow/.local/lib/python3.6/site-packages/airflow/models/dagbag.py", line 326, in _load_modules_from_file
    loader.exec_module(new_module)
  File "<frozen importlib._bootstrap_external>", line 678, in exec_module
  File "<frozen importlib._bootstrap>", line 219, in _call_with_frames_removed
  File "/opt/airflow/dags/mining_etl.py", line 5, in <module>
    from data_processing import *
ModuleNotFoundError: No module named 'data_processing'
[2023-04-15 23:19:44,755] {processor.py:625} WARNING - No viable dags retrieved from /opt/airflow/dags/mining_etl.py
[2023-04-15 23:19:44,791] {processor.py:170} INFO - Processing /opt/airflow/dags/mining_etl.py took 0.044 seconds
[2023-04-15 23:19:59,846] {processor.py:162} INFO - Started process (PID=98) to work on /opt/airflow/dags/mining_etl.py
[2023-04-15 23:19:59,849] {processor.py:613} INFO - Processing file /opt/airflow/dags/mining_etl.py for tasks to queue
[2023-04-15 23:19:59,850] {logging_mixin.py:109} INFO - [2023-04-15 23:19:59,850] {dagbag.py:496} INFO - Filling up the DagBag from /opt/airflow/dags/mining_etl.py
[2023-04-15 23:19:59,854] {logging_mixin.py:109} INFO - [2023-04-15 23:19:59,853] {dagbag.py:329} ERROR - Failed to import: /opt/airflow/dags/mining_etl.py
Traceback (most recent call last):
  File "/home/airflow/.local/lib/python3.6/site-packages/airflow/models/dagbag.py", line 326, in _load_modules_from_file
    loader.exec_module(new_module)
  File "<frozen importlib._bootstrap_external>", line 678, in exec_module
  File "<frozen importlib._bootstrap>", line 219, in _call_with_frames_removed
  File "/opt/airflow/dags/mining_etl.py", line 5, in <module>
    from data_processing import *
ModuleNotFoundError: No module named 'data_processing'
[2023-04-15 23:19:59,855] {processor.py:625} WARNING - No viable dags retrieved from /opt/airflow/dags/mining_etl.py
[2023-04-15 23:19:59,900] {processor.py:170} INFO - Processing /opt/airflow/dags/mining_etl.py took 0.063 seconds
[2023-04-15 23:20:07,900] {processor.py:162} INFO - Started process (PID=99) to work on /opt/airflow/dags/mining_etl.py
[2023-04-15 23:20:07,902] {processor.py:613} INFO - Processing file /opt/airflow/dags/mining_etl.py for tasks to queue
[2023-04-15 23:20:07,903] {logging_mixin.py:109} INFO - [2023-04-15 23:20:07,903] {dagbag.py:496} INFO - Filling up the DagBag from /opt/airflow/dags/mining_etl.py
[2023-04-15 23:20:07,910] {logging_mixin.py:109} INFO - [2023-04-15 23:20:07,908] {dagbag.py:329} ERROR - Failed to import: /opt/airflow/dags/mining_etl.py
Traceback (most recent call last):
  File "/home/airflow/.local/lib/python3.6/site-packages/airflow/models/dagbag.py", line 326, in _load_modules_from_file
    loader.exec_module(new_module)
  File "<frozen importlib._bootstrap_external>", line 678, in exec_module
  File "<frozen importlib._bootstrap>", line 219, in _call_with_frames_removed
  File "/opt/airflow/dags/mining_etl.py", line 5, in <module>
    from data_processing import *
ModuleNotFoundError: No module named 'data_processing'
[2023-04-15 23:20:07,911] {processor.py:625} WARNING - No viable dags retrieved from /opt/airflow/dags/mining_etl.py
[2023-04-15 23:20:07,979] {processor.py:170} INFO - Processing /opt/airflow/dags/mining_etl.py took 0.087 seconds
[2023-04-15 23:20:30,997] {processor.py:162} INFO - Started process (PID=100) to work on /opt/airflow/dags/mining_etl.py
[2023-04-15 23:20:30,999] {processor.py:613} INFO - Processing file /opt/airflow/dags/mining_etl.py for tasks to queue
[2023-04-15 23:20:30,999] {logging_mixin.py:109} INFO - [2023-04-15 23:20:30,999] {dagbag.py:496} INFO - Filling up the DagBag from /opt/airflow/dags/mining_etl.py
[2023-04-15 23:20:31,003] {logging_mixin.py:109} INFO - [2023-04-15 23:20:31,002] {dagbag.py:329} ERROR - Failed to import: /opt/airflow/dags/mining_etl.py
Traceback (most recent call last):
  File "/home/airflow/.local/lib/python3.6/site-packages/airflow/models/dagbag.py", line 326, in _load_modules_from_file
    loader.exec_module(new_module)
  File "<frozen importlib._bootstrap_external>", line 678, in exec_module
  File "<frozen importlib._bootstrap>", line 219, in _call_with_frames_removed
  File "/opt/airflow/dags/mining_etl.py", line 5, in <module>
    from data_processing import *
ModuleNotFoundError: No module named 'data_processing'
[2023-04-15 23:20:31,003] {processor.py:625} WARNING - No viable dags retrieved from /opt/airflow/dags/mining_etl.py
[2023-04-15 23:20:31,046] {processor.py:170} INFO - Processing /opt/airflow/dags/mining_etl.py took 0.053 seconds
[2023-04-15 23:21:01,129] {processor.py:162} INFO - Started process (PID=101) to work on /opt/airflow/dags/mining_etl.py
[2023-04-15 23:21:01,131] {processor.py:613} INFO - Processing file /opt/airflow/dags/mining_etl.py for tasks to queue
[2023-04-15 23:21:01,132] {logging_mixin.py:109} INFO - [2023-04-15 23:21:01,132] {dagbag.py:496} INFO - Filling up the DagBag from /opt/airflow/dags/mining_etl.py
[2023-04-15 23:21:01,138] {logging_mixin.py:109} INFO - [2023-04-15 23:21:01,136] {dagbag.py:329} ERROR - Failed to import: /opt/airflow/dags/mining_etl.py
Traceback (most recent call last):
  File "/home/airflow/.local/lib/python3.6/site-packages/airflow/models/dagbag.py", line 326, in _load_modules_from_file
    loader.exec_module(new_module)
  File "<frozen importlib._bootstrap_external>", line 678, in exec_module
  File "<frozen importlib._bootstrap>", line 219, in _call_with_frames_removed
  File "/opt/airflow/dags/mining_etl.py", line 5, in <module>
    from data_processing import *
ModuleNotFoundError: No module named 'data_processing'
[2023-04-15 23:21:01,139] {processor.py:625} WARNING - No viable dags retrieved from /opt/airflow/dags/mining_etl.py
[2023-04-15 23:21:01,183] {processor.py:170} INFO - Processing /opt/airflow/dags/mining_etl.py took 0.062 seconds
[2023-04-15 23:21:12,240] {processor.py:162} INFO - Started process (PID=102) to work on /opt/airflow/dags/mining_etl.py
[2023-04-15 23:21:12,243] {processor.py:613} INFO - Processing file /opt/airflow/dags/mining_etl.py for tasks to queue
[2023-04-15 23:21:12,244] {logging_mixin.py:109} INFO - [2023-04-15 23:21:12,244] {dagbag.py:496} INFO - Filling up the DagBag from /opt/airflow/dags/mining_etl.py
[2023-04-15 23:21:12,248] {logging_mixin.py:109} INFO - [2023-04-15 23:21:12,246] {dagbag.py:329} ERROR - Failed to import: /opt/airflow/dags/mining_etl.py
Traceback (most recent call last):
  File "/home/airflow/.local/lib/python3.6/site-packages/airflow/models/dagbag.py", line 326, in _load_modules_from_file
    loader.exec_module(new_module)
  File "<frozen importlib._bootstrap_external>", line 674, in exec_module
  File "<frozen importlib._bootstrap_external>", line 781, in get_code
  File "<frozen importlib._bootstrap_external>", line 741, in source_to_code
  File "<frozen importlib._bootstrap>", line 219, in _call_with_frames_removed
  File "/opt/airflow/dags/mining_etl.py", line 3
    path = os.path.abspath("C:\Users\pfaprado\Documents\GitHub\unit-testing")
                          ^
SyntaxError: (unicode error) 'unicodeescape' codec can't decode bytes in position 2-3: truncated \UXXXXXXXX escape
[2023-04-15 23:21:12,248] {processor.py:625} WARNING - No viable dags retrieved from /opt/airflow/dags/mining_etl.py
[2023-04-15 23:21:12,322] {processor.py:170} INFO - Processing /opt/airflow/dags/mining_etl.py took 0.096 seconds
[2023-04-15 23:21:28,307] {processor.py:162} INFO - Started process (PID=103) to work on /opt/airflow/dags/mining_etl.py
[2023-04-15 23:21:28,308] {processor.py:613} INFO - Processing file /opt/airflow/dags/mining_etl.py for tasks to queue
[2023-04-15 23:21:28,309] {logging_mixin.py:109} INFO - [2023-04-15 23:21:28,309] {dagbag.py:496} INFO - Filling up the DagBag from /opt/airflow/dags/mining_etl.py
[2023-04-15 23:21:28,312] {logging_mixin.py:109} INFO - [2023-04-15 23:21:28,311] {dagbag.py:329} ERROR - Failed to import: /opt/airflow/dags/mining_etl.py
Traceback (most recent call last):
  File "/home/airflow/.local/lib/python3.6/site-packages/airflow/models/dagbag.py", line 326, in _load_modules_from_file
    loader.exec_module(new_module)
  File "<frozen importlib._bootstrap_external>", line 678, in exec_module
  File "<frozen importlib._bootstrap>", line 219, in _call_with_frames_removed
  File "/opt/airflow/dags/mining_etl.py", line 5, in <module>
    from data_processing import *
ModuleNotFoundError: No module named 'data_processing'
[2023-04-15 23:21:28,313] {processor.py:625} WARNING - No viable dags retrieved from /opt/airflow/dags/mining_etl.py
[2023-04-15 23:21:28,360] {processor.py:170} INFO - Processing /opt/airflow/dags/mining_etl.py took 0.056 seconds
[2023-04-15 23:21:58,469] {processor.py:162} INFO - Started process (PID=104) to work on /opt/airflow/dags/mining_etl.py
[2023-04-15 23:21:58,472] {processor.py:613} INFO - Processing file /opt/airflow/dags/mining_etl.py for tasks to queue
[2023-04-15 23:21:58,473] {logging_mixin.py:109} INFO - [2023-04-15 23:21:58,473] {dagbag.py:496} INFO - Filling up the DagBag from /opt/airflow/dags/mining_etl.py
[2023-04-15 23:21:58,478] {logging_mixin.py:109} INFO - [2023-04-15 23:21:58,475] {dagbag.py:329} ERROR - Failed to import: /opt/airflow/dags/mining_etl.py
Traceback (most recent call last):
  File "/home/airflow/.local/lib/python3.6/site-packages/airflow/models/dagbag.py", line 326, in _load_modules_from_file
    loader.exec_module(new_module)
  File "<frozen importlib._bootstrap_external>", line 678, in exec_module
  File "<frozen importlib._bootstrap>", line 219, in _call_with_frames_removed
  File "/opt/airflow/dags/mining_etl.py", line 5, in <module>
    from data_processing import *
ModuleNotFoundError: No module named 'data_processing'
[2023-04-15 23:21:58,478] {processor.py:625} WARNING - No viable dags retrieved from /opt/airflow/dags/mining_etl.py
[2023-04-15 23:21:58,518] {processor.py:170} INFO - Processing /opt/airflow/dags/mining_etl.py took 0.053 seconds
[2023-04-15 23:22:28,623] {processor.py:162} INFO - Started process (PID=105) to work on /opt/airflow/dags/mining_etl.py
[2023-04-15 23:22:28,627] {processor.py:613} INFO - Processing file /opt/airflow/dags/mining_etl.py for tasks to queue
[2023-04-15 23:22:28,628] {logging_mixin.py:109} INFO - [2023-04-15 23:22:28,628] {dagbag.py:496} INFO - Filling up the DagBag from /opt/airflow/dags/mining_etl.py
[2023-04-15 23:22:28,634] {logging_mixin.py:109} INFO - [2023-04-15 23:22:28,632] {dagbag.py:329} ERROR - Failed to import: /opt/airflow/dags/mining_etl.py
Traceback (most recent call last):
  File "/home/airflow/.local/lib/python3.6/site-packages/airflow/models/dagbag.py", line 326, in _load_modules_from_file
    loader.exec_module(new_module)
  File "<frozen importlib._bootstrap_external>", line 678, in exec_module
  File "<frozen importlib._bootstrap>", line 219, in _call_with_frames_removed
  File "/opt/airflow/dags/mining_etl.py", line 5, in <module>
    from data_processing import *
ModuleNotFoundError: No module named 'data_processing'
[2023-04-15 23:22:28,635] {processor.py:625} WARNING - No viable dags retrieved from /opt/airflow/dags/mining_etl.py
[2023-04-15 23:22:28,683] {processor.py:170} INFO - Processing /opt/airflow/dags/mining_etl.py took 0.069 seconds
[2023-04-15 23:22:58,759] {processor.py:162} INFO - Started process (PID=106) to work on /opt/airflow/dags/mining_etl.py
[2023-04-15 23:22:58,763] {processor.py:613} INFO - Processing file /opt/airflow/dags/mining_etl.py for tasks to queue
[2023-04-15 23:22:58,766] {logging_mixin.py:109} INFO - [2023-04-15 23:22:58,766] {dagbag.py:496} INFO - Filling up the DagBag from /opt/airflow/dags/mining_etl.py
[2023-04-15 23:22:58,773] {logging_mixin.py:109} INFO - [2023-04-15 23:22:58,772] {dagbag.py:329} ERROR - Failed to import: /opt/airflow/dags/mining_etl.py
Traceback (most recent call last):
  File "/home/airflow/.local/lib/python3.6/site-packages/airflow/models/dagbag.py", line 326, in _load_modules_from_file
    loader.exec_module(new_module)
  File "<frozen importlib._bootstrap_external>", line 678, in exec_module
  File "<frozen importlib._bootstrap>", line 219, in _call_with_frames_removed
  File "/opt/airflow/dags/mining_etl.py", line 5, in <module>
    from data_processing import *
ModuleNotFoundError: No module named 'data_processing'
[2023-04-15 23:22:58,774] {processor.py:625} WARNING - No viable dags retrieved from /opt/airflow/dags/mining_etl.py
[2023-04-15 23:22:58,829] {processor.py:170} INFO - Processing /opt/airflow/dags/mining_etl.py took 0.084 seconds
[2023-04-15 23:23:28,856] {processor.py:162} INFO - Started process (PID=107) to work on /opt/airflow/dags/mining_etl.py
[2023-04-15 23:23:28,857] {processor.py:613} INFO - Processing file /opt/airflow/dags/mining_etl.py for tasks to queue
[2023-04-15 23:23:28,860] {logging_mixin.py:109} INFO - [2023-04-15 23:23:28,859] {dagbag.py:496} INFO - Filling up the DagBag from /opt/airflow/dags/mining_etl.py
[2023-04-15 23:23:28,864] {logging_mixin.py:109} INFO - [2023-04-15 23:23:28,863] {dagbag.py:329} ERROR - Failed to import: /opt/airflow/dags/mining_etl.py
Traceback (most recent call last):
  File "/home/airflow/.local/lib/python3.6/site-packages/airflow/models/dagbag.py", line 326, in _load_modules_from_file
    loader.exec_module(new_module)
  File "<frozen importlib._bootstrap_external>", line 678, in exec_module
  File "<frozen importlib._bootstrap>", line 219, in _call_with_frames_removed
  File "/opt/airflow/dags/mining_etl.py", line 5, in <module>
    from data_processing import *
ModuleNotFoundError: No module named 'data_processing'
[2023-04-15 23:23:28,865] {processor.py:625} WARNING - No viable dags retrieved from /opt/airflow/dags/mining_etl.py
[2023-04-15 23:23:28,991] {processor.py:170} INFO - Processing /opt/airflow/dags/mining_etl.py took 0.139 seconds
[2023-04-15 23:23:54,989] {processor.py:162} INFO - Started process (PID=108) to work on /opt/airflow/dags/mining_etl.py
[2023-04-15 23:23:55,043] {processor.py:613} INFO - Processing file /opt/airflow/dags/mining_etl.py for tasks to queue
[2023-04-15 23:23:55,044] {logging_mixin.py:109} INFO - [2023-04-15 23:23:55,044] {dagbag.py:496} INFO - Filling up the DagBag from /opt/airflow/dags/mining_etl.py
[2023-04-15 23:23:55,049] {logging_mixin.py:109} INFO - [2023-04-15 23:23:55,048] {dagbag.py:329} ERROR - Failed to import: /opt/airflow/dags/mining_etl.py
Traceback (most recent call last):
  File "/home/airflow/.local/lib/python3.6/site-packages/airflow/models/dagbag.py", line 326, in _load_modules_from_file
    loader.exec_module(new_module)
  File "<frozen importlib._bootstrap_external>", line 678, in exec_module
  File "<frozen importlib._bootstrap>", line 219, in _call_with_frames_removed
  File "/opt/airflow/dags/mining_etl.py", line 5, in <module>
    from data_processing import import_file, process_file, export_file
ModuleNotFoundError: No module named 'data_processing'
[2023-04-15 23:23:55,050] {processor.py:625} WARNING - No viable dags retrieved from /opt/airflow/dags/mining_etl.py
[2023-04-15 23:23:55,100] {processor.py:170} INFO - Processing /opt/airflow/dags/mining_etl.py took 0.126 seconds
[2023-04-15 23:24:25,168] {processor.py:162} INFO - Started process (PID=109) to work on /opt/airflow/dags/mining_etl.py
[2023-04-15 23:24:25,170] {processor.py:613} INFO - Processing file /opt/airflow/dags/mining_etl.py for tasks to queue
[2023-04-15 23:24:25,171] {logging_mixin.py:109} INFO - [2023-04-15 23:24:25,171] {dagbag.py:496} INFO - Filling up the DagBag from /opt/airflow/dags/mining_etl.py
[2023-04-15 23:24:25,173] {logging_mixin.py:109} INFO - [2023-04-15 23:24:25,173] {dagbag.py:329} ERROR - Failed to import: /opt/airflow/dags/mining_etl.py
Traceback (most recent call last):
  File "/home/airflow/.local/lib/python3.6/site-packages/airflow/models/dagbag.py", line 326, in _load_modules_from_file
    loader.exec_module(new_module)
  File "<frozen importlib._bootstrap_external>", line 678, in exec_module
  File "<frozen importlib._bootstrap>", line 219, in _call_with_frames_removed
  File "/opt/airflow/dags/mining_etl.py", line 5, in <module>
    from data_processing import import_file, process_file, export_file
ModuleNotFoundError: No module named 'data_processing'
[2023-04-15 23:24:25,175] {processor.py:625} WARNING - No viable dags retrieved from /opt/airflow/dags/mining_etl.py
[2023-04-15 23:24:25,226] {processor.py:170} INFO - Processing /opt/airflow/dags/mining_etl.py took 0.064 seconds
[2023-04-15 23:24:30,201] {processor.py:162} INFO - Started process (PID=110) to work on /opt/airflow/dags/mining_etl.py
[2023-04-15 23:24:30,257] {processor.py:613} INFO - Processing file /opt/airflow/dags/mining_etl.py for tasks to queue
[2023-04-15 23:24:30,258] {logging_mixin.py:109} INFO - [2023-04-15 23:24:30,258] {dagbag.py:496} INFO - Filling up the DagBag from /opt/airflow/dags/mining_etl.py
[2023-04-15 23:24:30,262] {logging_mixin.py:109} INFO - [2023-04-15 23:24:30,261] {dagbag.py:329} ERROR - Failed to import: /opt/airflow/dags/mining_etl.py
Traceback (most recent call last):
  File "/home/airflow/.local/lib/python3.6/site-packages/airflow/models/dagbag.py", line 326, in _load_modules_from_file
    loader.exec_module(new_module)
  File "<frozen importlib._bootstrap_external>", line 678, in exec_module
  File "<frozen importlib._bootstrap>", line 219, in _call_with_frames_removed
  File "/opt/airflow/dags/mining_etl.py", line 5, in <module>
    from data_processing.py import import_file, process_file, export_file
ModuleNotFoundError: No module named 'data_processing'
[2023-04-15 23:24:30,262] {processor.py:625} WARNING - No viable dags retrieved from /opt/airflow/dags/mining_etl.py
[2023-04-15 23:24:30,312] {processor.py:170} INFO - Processing /opt/airflow/dags/mining_etl.py took 0.116 seconds
[2023-04-15 23:24:32,264] {processor.py:162} INFO - Started process (PID=111) to work on /opt/airflow/dags/mining_etl.py
[2023-04-15 23:24:32,266] {processor.py:613} INFO - Processing file /opt/airflow/dags/mining_etl.py for tasks to queue
[2023-04-15 23:24:32,269] {logging_mixin.py:109} INFO - [2023-04-15 23:24:32,268] {dagbag.py:496} INFO - Filling up the DagBag from /opt/airflow/dags/mining_etl.py
[2023-04-15 23:24:32,275] {logging_mixin.py:109} INFO - [2023-04-15 23:24:32,274] {dagbag.py:329} ERROR - Failed to import: /opt/airflow/dags/mining_etl.py
Traceback (most recent call last):
  File "/home/airflow/.local/lib/python3.6/site-packages/airflow/models/dagbag.py", line 326, in _load_modules_from_file
    loader.exec_module(new_module)
  File "<frozen importlib._bootstrap_external>", line 678, in exec_module
  File "<frozen importlib._bootstrap>", line 219, in _call_with_frames_removed
  File "/opt/airflow/dags/mining_etl.py", line 5, in <module>
    from data_processing.py import import_file, process_file, export_file
ModuleNotFoundError: No module named 'data_processing'
[2023-04-15 23:24:32,276] {processor.py:625} WARNING - No viable dags retrieved from /opt/airflow/dags/mining_etl.py
[2023-04-15 23:24:32,323] {processor.py:170} INFO - Processing /opt/airflow/dags/mining_etl.py took 0.066 seconds
[2023-04-15 23:25:02,467] {processor.py:162} INFO - Started process (PID=112) to work on /opt/airflow/dags/mining_etl.py
[2023-04-15 23:25:02,469] {processor.py:613} INFO - Processing file /opt/airflow/dags/mining_etl.py for tasks to queue
[2023-04-15 23:25:02,470] {logging_mixin.py:109} INFO - [2023-04-15 23:25:02,469] {dagbag.py:496} INFO - Filling up the DagBag from /opt/airflow/dags/mining_etl.py
[2023-04-15 23:25:02,475] {logging_mixin.py:109} INFO - [2023-04-15 23:25:02,473] {dagbag.py:329} ERROR - Failed to import: /opt/airflow/dags/mining_etl.py
Traceback (most recent call last):
  File "/home/airflow/.local/lib/python3.6/site-packages/airflow/models/dagbag.py", line 326, in _load_modules_from_file
    loader.exec_module(new_module)
  File "<frozen importlib._bootstrap_external>", line 678, in exec_module
  File "<frozen importlib._bootstrap>", line 219, in _call_with_frames_removed
  File "/opt/airflow/dags/mining_etl.py", line 5, in <module>
    from data_processing.py import import_file, process_file, export_file
ModuleNotFoundError: No module named 'data_processing'
[2023-04-15 23:25:02,476] {processor.py:625} WARNING - No viable dags retrieved from /opt/airflow/dags/mining_etl.py
[2023-04-15 23:25:02,515] {processor.py:170} INFO - Processing /opt/airflow/dags/mining_etl.py took 0.053 seconds
[2023-04-15 23:25:32,640] {processor.py:162} INFO - Started process (PID=113) to work on /opt/airflow/dags/mining_etl.py
[2023-04-15 23:25:32,644] {processor.py:613} INFO - Processing file /opt/airflow/dags/mining_etl.py for tasks to queue
[2023-04-15 23:25:32,645] {logging_mixin.py:109} INFO - [2023-04-15 23:25:32,645] {dagbag.py:496} INFO - Filling up the DagBag from /opt/airflow/dags/mining_etl.py
[2023-04-15 23:25:32,651] {logging_mixin.py:109} INFO - [2023-04-15 23:25:32,649] {dagbag.py:329} ERROR - Failed to import: /opt/airflow/dags/mining_etl.py
Traceback (most recent call last):
  File "/home/airflow/.local/lib/python3.6/site-packages/airflow/models/dagbag.py", line 326, in _load_modules_from_file
    loader.exec_module(new_module)
  File "<frozen importlib._bootstrap_external>", line 678, in exec_module
  File "<frozen importlib._bootstrap>", line 219, in _call_with_frames_removed
  File "/opt/airflow/dags/mining_etl.py", line 5, in <module>
    from data_processing.py import import_file, process_file, export_file
ModuleNotFoundError: No module named 'data_processing'
[2023-04-15 23:25:32,651] {processor.py:625} WARNING - No viable dags retrieved from /opt/airflow/dags/mining_etl.py
[2023-04-15 23:25:32,705] {processor.py:170} INFO - Processing /opt/airflow/dags/mining_etl.py took 0.078 seconds
[2023-04-15 23:25:41,666] {processor.py:162} INFO - Started process (PID=114) to work on /opt/airflow/dags/mining_etl.py
[2023-04-15 23:25:41,668] {processor.py:613} INFO - Processing file /opt/airflow/dags/mining_etl.py for tasks to queue
[2023-04-15 23:25:41,669] {logging_mixin.py:109} INFO - [2023-04-15 23:25:41,669] {dagbag.py:496} INFO - Filling up the DagBag from /opt/airflow/dags/mining_etl.py
[2023-04-15 23:25:41,676] {logging_mixin.py:109} INFO - [2023-04-15 23:25:41,674] {dagbag.py:329} ERROR - Failed to import: /opt/airflow/dags/mining_etl.py
Traceback (most recent call last):
  File "/home/airflow/.local/lib/python3.6/site-packages/airflow/models/dagbag.py", line 326, in _load_modules_from_file
    loader.exec_module(new_module)
  File "<frozen importlib._bootstrap_external>", line 678, in exec_module
  File "<frozen importlib._bootstrap>", line 219, in _call_with_frames_removed
  File "/opt/airflow/dags/mining_etl.py", line 5, in <module>
    from data_processing.py import *
ModuleNotFoundError: No module named 'data_processing'
[2023-04-15 23:25:41,677] {processor.py:625} WARNING - No viable dags retrieved from /opt/airflow/dags/mining_etl.py
[2023-04-15 23:25:41,734] {processor.py:170} INFO - Processing /opt/airflow/dags/mining_etl.py took 0.071 seconds
[2023-04-15 23:26:00,805] {processor.py:162} INFO - Started process (PID=115) to work on /opt/airflow/dags/mining_etl.py
[2023-04-15 23:26:00,807] {processor.py:613} INFO - Processing file /opt/airflow/dags/mining_etl.py for tasks to queue
[2023-04-15 23:26:00,808] {logging_mixin.py:109} INFO - [2023-04-15 23:26:00,808] {dagbag.py:496} INFO - Filling up the DagBag from /opt/airflow/dags/mining_etl.py
[2023-04-15 23:26:00,812] {logging_mixin.py:109} INFO - [2023-04-15 23:26:00,811] {dagbag.py:329} ERROR - Failed to import: /opt/airflow/dags/mining_etl.py
Traceback (most recent call last):
  File "/home/airflow/.local/lib/python3.6/site-packages/airflow/models/dagbag.py", line 326, in _load_modules_from_file
    loader.exec_module(new_module)
  File "<frozen importlib._bootstrap_external>", line 678, in exec_module
  File "<frozen importlib._bootstrap>", line 219, in _call_with_frames_removed
  File "/opt/airflow/dags/mining_etl.py", line 5, in <module>
    import data_processing.py
ModuleNotFoundError: No module named 'data_processing'
[2023-04-15 23:26:00,813] {processor.py:625} WARNING - No viable dags retrieved from /opt/airflow/dags/mining_etl.py
[2023-04-15 23:26:00,854] {processor.py:170} INFO - Processing /opt/airflow/dags/mining_etl.py took 0.055 seconds
[2023-04-15 23:26:30,936] {processor.py:162} INFO - Started process (PID=116) to work on /opt/airflow/dags/mining_etl.py
[2023-04-15 23:26:30,952] {processor.py:613} INFO - Processing file /opt/airflow/dags/mining_etl.py for tasks to queue
[2023-04-15 23:26:30,954] {logging_mixin.py:109} INFO - [2023-04-15 23:26:30,953] {dagbag.py:496} INFO - Filling up the DagBag from /opt/airflow/dags/mining_etl.py
[2023-04-15 23:26:30,959] {logging_mixin.py:109} INFO - [2023-04-15 23:26:30,957] {dagbag.py:329} ERROR - Failed to import: /opt/airflow/dags/mining_etl.py
Traceback (most recent call last):
  File "/home/airflow/.local/lib/python3.6/site-packages/airflow/models/dagbag.py", line 326, in _load_modules_from_file
    loader.exec_module(new_module)
  File "<frozen importlib._bootstrap_external>", line 678, in exec_module
  File "<frozen importlib._bootstrap>", line 219, in _call_with_frames_removed
  File "/opt/airflow/dags/mining_etl.py", line 5, in <module>
    import data_processing.py
ModuleNotFoundError: No module named 'data_processing'
[2023-04-15 23:26:30,960] {processor.py:625} WARNING - No viable dags retrieved from /opt/airflow/dags/mining_etl.py
[2023-04-15 23:26:30,999] {processor.py:170} INFO - Processing /opt/airflow/dags/mining_etl.py took 0.070 seconds
[2023-04-15 23:26:54,024] {processor.py:162} INFO - Started process (PID=117) to work on /opt/airflow/dags/mining_etl.py
[2023-04-15 23:26:54,025] {processor.py:613} INFO - Processing file /opt/airflow/dags/mining_etl.py for tasks to queue
[2023-04-15 23:26:54,026] {logging_mixin.py:109} INFO - [2023-04-15 23:26:54,026] {dagbag.py:496} INFO - Filling up the DagBag from /opt/airflow/dags/mining_etl.py
[2023-04-15 23:26:54,029] {logging_mixin.py:109} INFO - [2023-04-15 23:26:54,029] {dagbag.py:329} ERROR - Failed to import: /opt/airflow/dags/mining_etl.py
Traceback (most recent call last):
  File "/home/airflow/.local/lib/python3.6/site-packages/airflow/models/dagbag.py", line 326, in _load_modules_from_file
    loader.exec_module(new_module)
  File "<frozen importlib._bootstrap_external>", line 678, in exec_module
  File "<frozen importlib._bootstrap>", line 219, in _call_with_frames_removed
  File "/opt/airflow/dags/mining_etl.py", line 5, in <module>
    import data_processing.py
ModuleNotFoundError: No module named 'data_processing'
[2023-04-15 23:26:54,030] {processor.py:625} WARNING - No viable dags retrieved from /opt/airflow/dags/mining_etl.py
[2023-04-15 23:26:54,120] {processor.py:170} INFO - Processing /opt/airflow/dags/mining_etl.py took 0.099 seconds
[2023-04-15 23:27:24,168] {processor.py:162} INFO - Started process (PID=118) to work on /opt/airflow/dags/mining_etl.py
[2023-04-15 23:27:24,170] {processor.py:613} INFO - Processing file /opt/airflow/dags/mining_etl.py for tasks to queue
[2023-04-15 23:27:24,172] {logging_mixin.py:109} INFO - [2023-04-15 23:27:24,171] {dagbag.py:496} INFO - Filling up the DagBag from /opt/airflow/dags/mining_etl.py
[2023-04-15 23:27:24,175] {logging_mixin.py:109} INFO - [2023-04-15 23:27:24,174] {dagbag.py:329} ERROR - Failed to import: /opt/airflow/dags/mining_etl.py
Traceback (most recent call last):
  File "/home/airflow/.local/lib/python3.6/site-packages/airflow/models/dagbag.py", line 326, in _load_modules_from_file
    loader.exec_module(new_module)
  File "<frozen importlib._bootstrap_external>", line 678, in exec_module
  File "<frozen importlib._bootstrap>", line 219, in _call_with_frames_removed
  File "/opt/airflow/dags/mining_etl.py", line 5, in <module>
    import data_processing.py
ModuleNotFoundError: No module named 'data_processing'
[2023-04-15 23:27:24,175] {processor.py:625} WARNING - No viable dags retrieved from /opt/airflow/dags/mining_etl.py
[2023-04-15 23:27:24,220] {processor.py:170} INFO - Processing /opt/airflow/dags/mining_etl.py took 0.058 seconds
[2023-04-15 23:27:54,350] {processor.py:162} INFO - Started process (PID=119) to work on /opt/airflow/dags/mining_etl.py
[2023-04-15 23:27:54,351] {processor.py:613} INFO - Processing file /opt/airflow/dags/mining_etl.py for tasks to queue
[2023-04-15 23:27:54,352] {logging_mixin.py:109} INFO - [2023-04-15 23:27:54,352] {dagbag.py:496} INFO - Filling up the DagBag from /opt/airflow/dags/mining_etl.py
[2023-04-15 23:27:54,357] {logging_mixin.py:109} INFO - [2023-04-15 23:27:54,355] {dagbag.py:329} ERROR - Failed to import: /opt/airflow/dags/mining_etl.py
Traceback (most recent call last):
  File "/home/airflow/.local/lib/python3.6/site-packages/airflow/models/dagbag.py", line 326, in _load_modules_from_file
    loader.exec_module(new_module)
  File "<frozen importlib._bootstrap_external>", line 678, in exec_module
  File "<frozen importlib._bootstrap>", line 219, in _call_with_frames_removed
  File "/opt/airflow/dags/mining_etl.py", line 5, in <module>
    import data_processing.py
ModuleNotFoundError: No module named 'data_processing'
[2023-04-15 23:27:54,358] {processor.py:625} WARNING - No viable dags retrieved from /opt/airflow/dags/mining_etl.py
[2023-04-15 23:27:54,410] {processor.py:170} INFO - Processing /opt/airflow/dags/mining_etl.py took 0.070 seconds
[2023-04-15 23:28:24,483] {processor.py:162} INFO - Started process (PID=120) to work on /opt/airflow/dags/mining_etl.py
[2023-04-15 23:28:24,487] {processor.py:613} INFO - Processing file /opt/airflow/dags/mining_etl.py for tasks to queue
[2023-04-15 23:28:24,489] {logging_mixin.py:109} INFO - [2023-04-15 23:28:24,489] {dagbag.py:496} INFO - Filling up the DagBag from /opt/airflow/dags/mining_etl.py
[2023-04-15 23:28:24,494] {logging_mixin.py:109} INFO - [2023-04-15 23:28:24,492] {dagbag.py:329} ERROR - Failed to import: /opt/airflow/dags/mining_etl.py
Traceback (most recent call last):
  File "/home/airflow/.local/lib/python3.6/site-packages/airflow/models/dagbag.py", line 326, in _load_modules_from_file
    loader.exec_module(new_module)
  File "<frozen importlib._bootstrap_external>", line 678, in exec_module
  File "<frozen importlib._bootstrap>", line 219, in _call_with_frames_removed
  File "/opt/airflow/dags/mining_etl.py", line 5, in <module>
    import data_processing.py
ModuleNotFoundError: No module named 'data_processing'
[2023-04-15 23:28:24,495] {processor.py:625} WARNING - No viable dags retrieved from /opt/airflow/dags/mining_etl.py
[2023-04-15 23:28:24,655] {processor.py:170} INFO - Processing /opt/airflow/dags/mining_etl.py took 0.181 seconds
[2023-04-15 23:28:54,769] {processor.py:162} INFO - Started process (PID=121) to work on /opt/airflow/dags/mining_etl.py
[2023-04-15 23:28:54,771] {processor.py:613} INFO - Processing file /opt/airflow/dags/mining_etl.py for tasks to queue
[2023-04-15 23:28:54,772] {logging_mixin.py:109} INFO - [2023-04-15 23:28:54,772] {dagbag.py:496} INFO - Filling up the DagBag from /opt/airflow/dags/mining_etl.py
[2023-04-15 23:28:54,777] {logging_mixin.py:109} INFO - [2023-04-15 23:28:54,776] {dagbag.py:329} ERROR - Failed to import: /opt/airflow/dags/mining_etl.py
Traceback (most recent call last):
  File "/home/airflow/.local/lib/python3.6/site-packages/airflow/models/dagbag.py", line 326, in _load_modules_from_file
    loader.exec_module(new_module)
  File "<frozen importlib._bootstrap_external>", line 678, in exec_module
  File "<frozen importlib._bootstrap>", line 219, in _call_with_frames_removed
  File "/opt/airflow/dags/mining_etl.py", line 5, in <module>
    import data_processing.py
ModuleNotFoundError: No module named 'data_processing'
[2023-04-15 23:28:54,778] {processor.py:625} WARNING - No viable dags retrieved from /opt/airflow/dags/mining_etl.py
[2023-04-15 23:28:54,825] {processor.py:170} INFO - Processing /opt/airflow/dags/mining_etl.py took 0.065 seconds
[2023-04-15 23:29:24,922] {processor.py:162} INFO - Started process (PID=122) to work on /opt/airflow/dags/mining_etl.py
[2023-04-15 23:29:24,924] {processor.py:613} INFO - Processing file /opt/airflow/dags/mining_etl.py for tasks to queue
[2023-04-15 23:29:24,925] {logging_mixin.py:109} INFO - [2023-04-15 23:29:24,925] {dagbag.py:496} INFO - Filling up the DagBag from /opt/airflow/dags/mining_etl.py
[2023-04-15 23:29:24,930] {logging_mixin.py:109} INFO - [2023-04-15 23:29:24,928] {dagbag.py:329} ERROR - Failed to import: /opt/airflow/dags/mining_etl.py
Traceback (most recent call last):
  File "/home/airflow/.local/lib/python3.6/site-packages/airflow/models/dagbag.py", line 326, in _load_modules_from_file
    loader.exec_module(new_module)
  File "<frozen importlib._bootstrap_external>", line 678, in exec_module
  File "<frozen importlib._bootstrap>", line 219, in _call_with_frames_removed
  File "/opt/airflow/dags/mining_etl.py", line 5, in <module>
    import data_processing.py
ModuleNotFoundError: No module named 'data_processing'
[2023-04-15 23:29:24,930] {processor.py:625} WARNING - No viable dags retrieved from /opt/airflow/dags/mining_etl.py
[2023-04-15 23:29:24,975] {processor.py:170} INFO - Processing /opt/airflow/dags/mining_etl.py took 0.060 seconds
[2023-04-15 23:29:55,031] {processor.py:162} INFO - Started process (PID=123) to work on /opt/airflow/dags/mining_etl.py
[2023-04-15 23:29:55,032] {processor.py:613} INFO - Processing file /opt/airflow/dags/mining_etl.py for tasks to queue
[2023-04-15 23:29:55,032] {logging_mixin.py:109} INFO - [2023-04-15 23:29:55,032] {dagbag.py:496} INFO - Filling up the DagBag from /opt/airflow/dags/mining_etl.py
[2023-04-15 23:29:55,035] {logging_mixin.py:109} INFO - [2023-04-15 23:29:55,034] {dagbag.py:329} ERROR - Failed to import: /opt/airflow/dags/mining_etl.py
Traceback (most recent call last):
  File "/home/airflow/.local/lib/python3.6/site-packages/airflow/models/dagbag.py", line 326, in _load_modules_from_file
    loader.exec_module(new_module)
  File "<frozen importlib._bootstrap_external>", line 678, in exec_module
  File "<frozen importlib._bootstrap>", line 219, in _call_with_frames_removed
  File "/opt/airflow/dags/mining_etl.py", line 5, in <module>
    import data_processing.py
ModuleNotFoundError: No module named 'data_processing'
[2023-04-15 23:29:55,035] {processor.py:625} WARNING - No viable dags retrieved from /opt/airflow/dags/mining_etl.py
[2023-04-15 23:29:55,082] {processor.py:170} INFO - Processing /opt/airflow/dags/mining_etl.py took 0.055 seconds
[2023-04-15 23:30:25,136] {processor.py:162} INFO - Started process (PID=124) to work on /opt/airflow/dags/mining_etl.py
[2023-04-15 23:30:25,161] {processor.py:613} INFO - Processing file /opt/airflow/dags/mining_etl.py for tasks to queue
[2023-04-15 23:30:25,162] {logging_mixin.py:109} INFO - [2023-04-15 23:30:25,161] {dagbag.py:496} INFO - Filling up the DagBag from /opt/airflow/dags/mining_etl.py
[2023-04-15 23:30:25,164] {logging_mixin.py:109} INFO - [2023-04-15 23:30:25,163] {dagbag.py:329} ERROR - Failed to import: /opt/airflow/dags/mining_etl.py
Traceback (most recent call last):
  File "/home/airflow/.local/lib/python3.6/site-packages/airflow/models/dagbag.py", line 326, in _load_modules_from_file
    loader.exec_module(new_module)
  File "<frozen importlib._bootstrap_external>", line 678, in exec_module
  File "<frozen importlib._bootstrap>", line 219, in _call_with_frames_removed
  File "/opt/airflow/dags/mining_etl.py", line 5, in <module>
    import data_processing.py
ModuleNotFoundError: No module named 'data_processing'
[2023-04-15 23:30:25,164] {processor.py:625} WARNING - No viable dags retrieved from /opt/airflow/dags/mining_etl.py
[2023-04-15 23:30:25,210] {processor.py:170} INFO - Processing /opt/airflow/dags/mining_etl.py took 0.077 seconds
[2023-04-15 23:30:55,291] {processor.py:162} INFO - Started process (PID=125) to work on /opt/airflow/dags/mining_etl.py
[2023-04-15 23:30:55,293] {processor.py:613} INFO - Processing file /opt/airflow/dags/mining_etl.py for tasks to queue
[2023-04-15 23:30:55,294] {logging_mixin.py:109} INFO - [2023-04-15 23:30:55,294] {dagbag.py:496} INFO - Filling up the DagBag from /opt/airflow/dags/mining_etl.py
[2023-04-15 23:30:55,302] {logging_mixin.py:109} INFO - [2023-04-15 23:30:55,298] {dagbag.py:329} ERROR - Failed to import: /opt/airflow/dags/mining_etl.py
Traceback (most recent call last):
  File "/home/airflow/.local/lib/python3.6/site-packages/airflow/models/dagbag.py", line 326, in _load_modules_from_file
    loader.exec_module(new_module)
  File "<frozen importlib._bootstrap_external>", line 678, in exec_module
  File "<frozen importlib._bootstrap>", line 219, in _call_with_frames_removed
  File "/opt/airflow/dags/mining_etl.py", line 5, in <module>
    import data_processing.py
ModuleNotFoundError: No module named 'data_processing'
[2023-04-15 23:30:55,303] {processor.py:625} WARNING - No viable dags retrieved from /opt/airflow/dags/mining_etl.py
[2023-04-15 23:30:55,355] {processor.py:170} INFO - Processing /opt/airflow/dags/mining_etl.py took 0.073 seconds
[2023-04-15 23:31:25,435] {processor.py:162} INFO - Started process (PID=126) to work on /opt/airflow/dags/mining_etl.py
[2023-04-15 23:31:25,440] {processor.py:613} INFO - Processing file /opt/airflow/dags/mining_etl.py for tasks to queue
[2023-04-15 23:31:25,442] {logging_mixin.py:109} INFO - [2023-04-15 23:31:25,442] {dagbag.py:496} INFO - Filling up the DagBag from /opt/airflow/dags/mining_etl.py
[2023-04-15 23:31:25,447] {logging_mixin.py:109} INFO - [2023-04-15 23:31:25,446] {dagbag.py:329} ERROR - Failed to import: /opt/airflow/dags/mining_etl.py
Traceback (most recent call last):
  File "/home/airflow/.local/lib/python3.6/site-packages/airflow/models/dagbag.py", line 326, in _load_modules_from_file
    loader.exec_module(new_module)
  File "<frozen importlib._bootstrap_external>", line 678, in exec_module
  File "<frozen importlib._bootstrap>", line 219, in _call_with_frames_removed
  File "/opt/airflow/dags/mining_etl.py", line 5, in <module>
    import data_processing.py
ModuleNotFoundError: No module named 'data_processing'
[2023-04-15 23:31:25,448] {processor.py:625} WARNING - No viable dags retrieved from /opt/airflow/dags/mining_etl.py
[2023-04-15 23:31:25,492] {processor.py:170} INFO - Processing /opt/airflow/dags/mining_etl.py took 0.064 seconds
[2023-04-15 23:31:55,587] {processor.py:162} INFO - Started process (PID=127) to work on /opt/airflow/dags/mining_etl.py
[2023-04-15 23:31:55,589] {processor.py:613} INFO - Processing file /opt/airflow/dags/mining_etl.py for tasks to queue
[2023-04-15 23:31:55,590] {logging_mixin.py:109} INFO - [2023-04-15 23:31:55,590] {dagbag.py:496} INFO - Filling up the DagBag from /opt/airflow/dags/mining_etl.py
[2023-04-15 23:31:55,594] {logging_mixin.py:109} INFO - [2023-04-15 23:31:55,593] {dagbag.py:329} ERROR - Failed to import: /opt/airflow/dags/mining_etl.py
Traceback (most recent call last):
  File "/home/airflow/.local/lib/python3.6/site-packages/airflow/models/dagbag.py", line 326, in _load_modules_from_file
    loader.exec_module(new_module)
  File "<frozen importlib._bootstrap_external>", line 678, in exec_module
  File "<frozen importlib._bootstrap>", line 219, in _call_with_frames_removed
  File "/opt/airflow/dags/mining_etl.py", line 5, in <module>
    import data_processing.py
ModuleNotFoundError: No module named 'data_processing'
[2023-04-15 23:31:55,595] {processor.py:625} WARNING - No viable dags retrieved from /opt/airflow/dags/mining_etl.py
[2023-04-15 23:31:55,704] {processor.py:170} INFO - Processing /opt/airflow/dags/mining_etl.py took 0.121 seconds
[2023-04-15 23:32:25,806] {processor.py:162} INFO - Started process (PID=128) to work on /opt/airflow/dags/mining_etl.py
[2023-04-15 23:32:25,818] {processor.py:613} INFO - Processing file /opt/airflow/dags/mining_etl.py for tasks to queue
[2023-04-15 23:32:25,819] {logging_mixin.py:109} INFO - [2023-04-15 23:32:25,819] {dagbag.py:496} INFO - Filling up the DagBag from /opt/airflow/dags/mining_etl.py
[2023-04-15 23:32:25,824] {logging_mixin.py:109} INFO - [2023-04-15 23:32:25,822] {dagbag.py:329} ERROR - Failed to import: /opt/airflow/dags/mining_etl.py
Traceback (most recent call last):
  File "/home/airflow/.local/lib/python3.6/site-packages/airflow/models/dagbag.py", line 326, in _load_modules_from_file
    loader.exec_module(new_module)
  File "<frozen importlib._bootstrap_external>", line 678, in exec_module
  File "<frozen importlib._bootstrap>", line 219, in _call_with_frames_removed
  File "/opt/airflow/dags/mining_etl.py", line 5, in <module>
    import data_processing.py
ModuleNotFoundError: No module named 'data_processing'
[2023-04-15 23:32:25,824] {processor.py:625} WARNING - No viable dags retrieved from /opt/airflow/dags/mining_etl.py
[2023-04-15 23:32:25,874] {processor.py:170} INFO - Processing /opt/airflow/dags/mining_etl.py took 0.081 seconds
[2023-04-15 23:32:55,925] {processor.py:162} INFO - Started process (PID=129) to work on /opt/airflow/dags/mining_etl.py
[2023-04-15 23:32:55,928] {processor.py:613} INFO - Processing file /opt/airflow/dags/mining_etl.py for tasks to queue
[2023-04-15 23:32:55,934] {logging_mixin.py:109} INFO - [2023-04-15 23:32:55,934] {dagbag.py:496} INFO - Filling up the DagBag from /opt/airflow/dags/mining_etl.py
[2023-04-15 23:32:55,938] {logging_mixin.py:109} INFO - [2023-04-15 23:32:55,937] {dagbag.py:329} ERROR - Failed to import: /opt/airflow/dags/mining_etl.py
Traceback (most recent call last):
  File "/home/airflow/.local/lib/python3.6/site-packages/airflow/models/dagbag.py", line 326, in _load_modules_from_file
    loader.exec_module(new_module)
  File "<frozen importlib._bootstrap_external>", line 678, in exec_module
  File "<frozen importlib._bootstrap>", line 219, in _call_with_frames_removed
  File "/opt/airflow/dags/mining_etl.py", line 5, in <module>
    import data_processing.py
ModuleNotFoundError: No module named 'data_processing'
[2023-04-15 23:32:55,939] {processor.py:625} WARNING - No viable dags retrieved from /opt/airflow/dags/mining_etl.py
[2023-04-15 23:32:56,080] {processor.py:170} INFO - Processing /opt/airflow/dags/mining_etl.py took 0.162 seconds
[2023-04-15 23:33:26,175] {processor.py:162} INFO - Started process (PID=130) to work on /opt/airflow/dags/mining_etl.py
[2023-04-15 23:33:26,197] {processor.py:613} INFO - Processing file /opt/airflow/dags/mining_etl.py for tasks to queue
[2023-04-15 23:33:26,198] {logging_mixin.py:109} INFO - [2023-04-15 23:33:26,198] {dagbag.py:496} INFO - Filling up the DagBag from /opt/airflow/dags/mining_etl.py
[2023-04-15 23:33:26,201] {logging_mixin.py:109} INFO - [2023-04-15 23:33:26,200] {dagbag.py:329} ERROR - Failed to import: /opt/airflow/dags/mining_etl.py
Traceback (most recent call last):
  File "/home/airflow/.local/lib/python3.6/site-packages/airflow/models/dagbag.py", line 326, in _load_modules_from_file
    loader.exec_module(new_module)
  File "<frozen importlib._bootstrap_external>", line 678, in exec_module
  File "<frozen importlib._bootstrap>", line 219, in _call_with_frames_removed
  File "/opt/airflow/dags/mining_etl.py", line 5, in <module>
    import data_processing.py
ModuleNotFoundError: No module named 'data_processing'
[2023-04-15 23:33:26,201] {processor.py:625} WARNING - No viable dags retrieved from /opt/airflow/dags/mining_etl.py
[2023-04-15 23:33:26,272] {processor.py:170} INFO - Processing /opt/airflow/dags/mining_etl.py took 0.102 seconds
[2023-04-15 23:33:56,297] {processor.py:162} INFO - Started process (PID=131) to work on /opt/airflow/dags/mining_etl.py
[2023-04-15 23:33:56,310] {processor.py:613} INFO - Processing file /opt/airflow/dags/mining_etl.py for tasks to queue
[2023-04-15 23:33:56,311] {logging_mixin.py:109} INFO - [2023-04-15 23:33:56,311] {dagbag.py:496} INFO - Filling up the DagBag from /opt/airflow/dags/mining_etl.py
[2023-04-15 23:33:56,316] {logging_mixin.py:109} INFO - [2023-04-15 23:33:56,314] {dagbag.py:329} ERROR - Failed to import: /opt/airflow/dags/mining_etl.py
Traceback (most recent call last):
  File "/home/airflow/.local/lib/python3.6/site-packages/airflow/models/dagbag.py", line 326, in _load_modules_from_file
    loader.exec_module(new_module)
  File "<frozen importlib._bootstrap_external>", line 678, in exec_module
  File "<frozen importlib._bootstrap>", line 219, in _call_with_frames_removed
  File "/opt/airflow/dags/mining_etl.py", line 5, in <module>
    import data_processing.py
ModuleNotFoundError: No module named 'data_processing'
[2023-04-15 23:33:56,317] {processor.py:625} WARNING - No viable dags retrieved from /opt/airflow/dags/mining_etl.py
[2023-04-15 23:33:56,382] {processor.py:170} INFO - Processing /opt/airflow/dags/mining_etl.py took 0.090 seconds
[2023-04-15 23:34:26,476] {processor.py:162} INFO - Started process (PID=132) to work on /opt/airflow/dags/mining_etl.py
[2023-04-15 23:34:26,479] {processor.py:613} INFO - Processing file /opt/airflow/dags/mining_etl.py for tasks to queue
[2023-04-15 23:34:26,480] {logging_mixin.py:109} INFO - [2023-04-15 23:34:26,480] {dagbag.py:496} INFO - Filling up the DagBag from /opt/airflow/dags/mining_etl.py
[2023-04-15 23:34:26,484] {logging_mixin.py:109} INFO - [2023-04-15 23:34:26,482] {dagbag.py:329} ERROR - Failed to import: /opt/airflow/dags/mining_etl.py
Traceback (most recent call last):
  File "/home/airflow/.local/lib/python3.6/site-packages/airflow/models/dagbag.py", line 326, in _load_modules_from_file
    loader.exec_module(new_module)
  File "<frozen importlib._bootstrap_external>", line 678, in exec_module
  File "<frozen importlib._bootstrap>", line 219, in _call_with_frames_removed
  File "/opt/airflow/dags/mining_etl.py", line 5, in <module>
    import data_processing.py
ModuleNotFoundError: No module named 'data_processing'
[2023-04-15 23:34:26,484] {processor.py:625} WARNING - No viable dags retrieved from /opt/airflow/dags/mining_etl.py
[2023-04-15 23:34:26,554] {processor.py:170} INFO - Processing /opt/airflow/dags/mining_etl.py took 0.092 seconds
[2023-04-15 23:34:56,604] {processor.py:162} INFO - Started process (PID=133) to work on /opt/airflow/dags/mining_etl.py
[2023-04-15 23:34:56,606] {processor.py:613} INFO - Processing file /opt/airflow/dags/mining_etl.py for tasks to queue
[2023-04-15 23:34:56,607] {logging_mixin.py:109} INFO - [2023-04-15 23:34:56,607] {dagbag.py:496} INFO - Filling up the DagBag from /opt/airflow/dags/mining_etl.py
[2023-04-15 23:34:56,610] {logging_mixin.py:109} INFO - [2023-04-15 23:34:56,609] {dagbag.py:329} ERROR - Failed to import: /opt/airflow/dags/mining_etl.py
Traceback (most recent call last):
  File "/home/airflow/.local/lib/python3.6/site-packages/airflow/models/dagbag.py", line 326, in _load_modules_from_file
    loader.exec_module(new_module)
  File "<frozen importlib._bootstrap_external>", line 678, in exec_module
  File "<frozen importlib._bootstrap>", line 219, in _call_with_frames_removed
  File "/opt/airflow/dags/mining_etl.py", line 5, in <module>
    import data_processing.py
ModuleNotFoundError: No module named 'data_processing'
[2023-04-15 23:34:56,611] {processor.py:625} WARNING - No viable dags retrieved from /opt/airflow/dags/mining_etl.py
[2023-04-15 23:34:56,658] {processor.py:170} INFO - Processing /opt/airflow/dags/mining_etl.py took 0.058 seconds
[2023-04-15 23:35:13,722] {processor.py:162} INFO - Started process (PID=134) to work on /opt/airflow/dags/mining_etl.py
[2023-04-15 23:35:13,725] {processor.py:613} INFO - Processing file /opt/airflow/dags/mining_etl.py for tasks to queue
[2023-04-15 23:35:13,726] {logging_mixin.py:109} INFO - [2023-04-15 23:35:13,726] {dagbag.py:496} INFO - Filling up the DagBag from /opt/airflow/dags/mining_etl.py
[2023-04-15 23:35:13,733] {logging_mixin.py:109} INFO - [2023-04-15 23:35:13,731] {dagbag.py:329} ERROR - Failed to import: /opt/airflow/dags/mining_etl.py
Traceback (most recent call last):
  File "/home/airflow/.local/lib/python3.6/site-packages/airflow/models/dagbag.py", line 326, in _load_modules_from_file
    loader.exec_module(new_module)
  File "<frozen importlib._bootstrap_external>", line 678, in exec_module
  File "<frozen importlib._bootstrap>", line 219, in _call_with_frames_removed
  File "/opt/airflow/dags/mining_etl.py", line 5, in <module>
    import data_processing
ModuleNotFoundError: No module named 'data_processing'
[2023-04-15 23:35:13,733] {processor.py:625} WARNING - No viable dags retrieved from /opt/airflow/dags/mining_etl.py
[2023-04-15 23:35:13,797] {processor.py:170} INFO - Processing /opt/airflow/dags/mining_etl.py took 0.088 seconds
[2023-04-15 23:35:43,839] {processor.py:162} INFO - Started process (PID=135) to work on /opt/airflow/dags/mining_etl.py
[2023-04-15 23:35:43,842] {processor.py:613} INFO - Processing file /opt/airflow/dags/mining_etl.py for tasks to queue
[2023-04-15 23:35:43,844] {logging_mixin.py:109} INFO - [2023-04-15 23:35:43,844] {dagbag.py:496} INFO - Filling up the DagBag from /opt/airflow/dags/mining_etl.py
[2023-04-15 23:35:43,847] {logging_mixin.py:109} INFO - [2023-04-15 23:35:43,847] {dagbag.py:329} ERROR - Failed to import: /opt/airflow/dags/mining_etl.py
Traceback (most recent call last):
  File "/home/airflow/.local/lib/python3.6/site-packages/airflow/models/dagbag.py", line 326, in _load_modules_from_file
    loader.exec_module(new_module)
  File "<frozen importlib._bootstrap_external>", line 678, in exec_module
  File "<frozen importlib._bootstrap>", line 219, in _call_with_frames_removed
  File "/opt/airflow/dags/mining_etl.py", line 5, in <module>
    import data_processing
ModuleNotFoundError: No module named 'data_processing'
[2023-04-15 23:35:43,848] {processor.py:625} WARNING - No viable dags retrieved from /opt/airflow/dags/mining_etl.py
[2023-04-15 23:35:43,890] {processor.py:170} INFO - Processing /opt/airflow/dags/mining_etl.py took 0.057 seconds
[2023-04-15 23:36:13,999] {processor.py:162} INFO - Started process (PID=136) to work on /opt/airflow/dags/mining_etl.py
[2023-04-15 23:36:14,000] {processor.py:613} INFO - Processing file /opt/airflow/dags/mining_etl.py for tasks to queue
[2023-04-15 23:36:14,002] {logging_mixin.py:109} INFO - [2023-04-15 23:36:14,001] {dagbag.py:496} INFO - Filling up the DagBag from /opt/airflow/dags/mining_etl.py
[2023-04-15 23:36:14,006] {logging_mixin.py:109} INFO - [2023-04-15 23:36:14,005] {dagbag.py:329} ERROR - Failed to import: /opt/airflow/dags/mining_etl.py
Traceback (most recent call last):
  File "/home/airflow/.local/lib/python3.6/site-packages/airflow/models/dagbag.py", line 326, in _load_modules_from_file
    loader.exec_module(new_module)
  File "<frozen importlib._bootstrap_external>", line 678, in exec_module
  File "<frozen importlib._bootstrap>", line 219, in _call_with_frames_removed
  File "/opt/airflow/dags/mining_etl.py", line 5, in <module>
    import data_processing
ModuleNotFoundError: No module named 'data_processing'
[2023-04-15 23:36:14,007] {processor.py:625} WARNING - No viable dags retrieved from /opt/airflow/dags/mining_etl.py
[2023-04-15 23:36:14,055] {processor.py:170} INFO - Processing /opt/airflow/dags/mining_etl.py took 0.066 seconds
[2023-04-15 23:36:44,147] {processor.py:162} INFO - Started process (PID=137) to work on /opt/airflow/dags/mining_etl.py
[2023-04-15 23:36:44,151] {processor.py:613} INFO - Processing file /opt/airflow/dags/mining_etl.py for tasks to queue
[2023-04-15 23:36:44,152] {logging_mixin.py:109} INFO - [2023-04-15 23:36:44,152] {dagbag.py:496} INFO - Filling up the DagBag from /opt/airflow/dags/mining_etl.py
[2023-04-15 23:36:44,160] {logging_mixin.py:109} INFO - [2023-04-15 23:36:44,156] {dagbag.py:329} ERROR - Failed to import: /opt/airflow/dags/mining_etl.py
Traceback (most recent call last):
  File "/home/airflow/.local/lib/python3.6/site-packages/airflow/models/dagbag.py", line 326, in _load_modules_from_file
    loader.exec_module(new_module)
  File "<frozen importlib._bootstrap_external>", line 678, in exec_module
  File "<frozen importlib._bootstrap>", line 219, in _call_with_frames_removed
  File "/opt/airflow/dags/mining_etl.py", line 5, in <module>
    import data_processing
ModuleNotFoundError: No module named 'data_processing'
[2023-04-15 23:36:44,160] {processor.py:625} WARNING - No viable dags retrieved from /opt/airflow/dags/mining_etl.py
[2023-04-15 23:36:44,207] {processor.py:170} INFO - Processing /opt/airflow/dags/mining_etl.py took 0.072 seconds
[2023-04-15 23:37:14,249] {processor.py:162} INFO - Started process (PID=138) to work on /opt/airflow/dags/mining_etl.py
[2023-04-15 23:37:14,254] {processor.py:613} INFO - Processing file /opt/airflow/dags/mining_etl.py for tasks to queue
[2023-04-15 23:37:14,256] {logging_mixin.py:109} INFO - [2023-04-15 23:37:14,255] {dagbag.py:496} INFO - Filling up the DagBag from /opt/airflow/dags/mining_etl.py
[2023-04-15 23:37:14,262] {logging_mixin.py:109} INFO - [2023-04-15 23:37:14,260] {dagbag.py:329} ERROR - Failed to import: /opt/airflow/dags/mining_etl.py
Traceback (most recent call last):
  File "/home/airflow/.local/lib/python3.6/site-packages/airflow/models/dagbag.py", line 326, in _load_modules_from_file
    loader.exec_module(new_module)
  File "<frozen importlib._bootstrap_external>", line 678, in exec_module
  File "<frozen importlib._bootstrap>", line 219, in _call_with_frames_removed
  File "/opt/airflow/dags/mining_etl.py", line 5, in <module>
    import data_processing
ModuleNotFoundError: No module named 'data_processing'
[2023-04-15 23:37:14,262] {processor.py:625} WARNING - No viable dags retrieved from /opt/airflow/dags/mining_etl.py
[2023-04-15 23:37:14,328] {processor.py:170} INFO - Processing /opt/airflow/dags/mining_etl.py took 0.088 seconds
[2023-04-15 23:37:44,387] {processor.py:162} INFO - Started process (PID=139) to work on /opt/airflow/dags/mining_etl.py
[2023-04-15 23:37:44,388] {processor.py:613} INFO - Processing file /opt/airflow/dags/mining_etl.py for tasks to queue
[2023-04-15 23:37:44,389] {logging_mixin.py:109} INFO - [2023-04-15 23:37:44,389] {dagbag.py:496} INFO - Filling up the DagBag from /opt/airflow/dags/mining_etl.py
[2023-04-15 23:37:44,392] {logging_mixin.py:109} INFO - [2023-04-15 23:37:44,391] {dagbag.py:329} ERROR - Failed to import: /opt/airflow/dags/mining_etl.py
Traceback (most recent call last):
  File "/home/airflow/.local/lib/python3.6/site-packages/airflow/models/dagbag.py", line 326, in _load_modules_from_file
    loader.exec_module(new_module)
  File "<frozen importlib._bootstrap_external>", line 678, in exec_module
  File "<frozen importlib._bootstrap>", line 219, in _call_with_frames_removed
  File "/opt/airflow/dags/mining_etl.py", line 5, in <module>
    import data_processing
ModuleNotFoundError: No module named 'data_processing'
[2023-04-15 23:37:44,392] {processor.py:625} WARNING - No viable dags retrieved from /opt/airflow/dags/mining_etl.py
[2023-04-15 23:37:44,430] {processor.py:170} INFO - Processing /opt/airflow/dags/mining_etl.py took 0.047 seconds
[2023-04-15 23:38:14,508] {processor.py:162} INFO - Started process (PID=140) to work on /opt/airflow/dags/mining_etl.py
[2023-04-15 23:38:14,510] {processor.py:613} INFO - Processing file /opt/airflow/dags/mining_etl.py for tasks to queue
[2023-04-15 23:38:14,511] {logging_mixin.py:109} INFO - [2023-04-15 23:38:14,511] {dagbag.py:496} INFO - Filling up the DagBag from /opt/airflow/dags/mining_etl.py
[2023-04-15 23:38:14,515] {logging_mixin.py:109} INFO - [2023-04-15 23:38:14,514] {dagbag.py:329} ERROR - Failed to import: /opt/airflow/dags/mining_etl.py
Traceback (most recent call last):
  File "/home/airflow/.local/lib/python3.6/site-packages/airflow/models/dagbag.py", line 326, in _load_modules_from_file
    loader.exec_module(new_module)
  File "<frozen importlib._bootstrap_external>", line 678, in exec_module
  File "<frozen importlib._bootstrap>", line 219, in _call_with_frames_removed
  File "/opt/airflow/dags/mining_etl.py", line 5, in <module>
    import data_processing
ModuleNotFoundError: No module named 'data_processing'
[2023-04-15 23:38:14,515] {processor.py:625} WARNING - No viable dags retrieved from /opt/airflow/dags/mining_etl.py
[2023-04-15 23:38:14,565] {processor.py:170} INFO - Processing /opt/airflow/dags/mining_etl.py took 0.067 seconds
[2023-04-15 23:38:44,663] {processor.py:162} INFO - Started process (PID=141) to work on /opt/airflow/dags/mining_etl.py
[2023-04-15 23:38:44,665] {processor.py:613} INFO - Processing file /opt/airflow/dags/mining_etl.py for tasks to queue
[2023-04-15 23:38:44,666] {logging_mixin.py:109} INFO - [2023-04-15 23:38:44,666] {dagbag.py:496} INFO - Filling up the DagBag from /opt/airflow/dags/mining_etl.py
[2023-04-15 23:38:44,670] {logging_mixin.py:109} INFO - [2023-04-15 23:38:44,669] {dagbag.py:329} ERROR - Failed to import: /opt/airflow/dags/mining_etl.py
Traceback (most recent call last):
  File "/home/airflow/.local/lib/python3.6/site-packages/airflow/models/dagbag.py", line 326, in _load_modules_from_file
    loader.exec_module(new_module)
  File "<frozen importlib._bootstrap_external>", line 678, in exec_module
  File "<frozen importlib._bootstrap>", line 219, in _call_with_frames_removed
  File "/opt/airflow/dags/mining_etl.py", line 5, in <module>
    import data_processing
ModuleNotFoundError: No module named 'data_processing'
[2023-04-15 23:38:44,671] {processor.py:625} WARNING - No viable dags retrieved from /opt/airflow/dags/mining_etl.py
[2023-04-15 23:38:44,761] {processor.py:170} INFO - Processing /opt/airflow/dags/mining_etl.py took 0.103 seconds
[2023-04-15 23:39:14,823] {processor.py:162} INFO - Started process (PID=142) to work on /opt/airflow/dags/mining_etl.py
[2023-04-15 23:39:14,826] {processor.py:613} INFO - Processing file /opt/airflow/dags/mining_etl.py for tasks to queue
[2023-04-15 23:39:14,827] {logging_mixin.py:109} INFO - [2023-04-15 23:39:14,827] {dagbag.py:496} INFO - Filling up the DagBag from /opt/airflow/dags/mining_etl.py
[2023-04-15 23:39:14,833] {logging_mixin.py:109} INFO - [2023-04-15 23:39:14,831] {dagbag.py:329} ERROR - Failed to import: /opt/airflow/dags/mining_etl.py
Traceback (most recent call last):
  File "/home/airflow/.local/lib/python3.6/site-packages/airflow/models/dagbag.py", line 326, in _load_modules_from_file
    loader.exec_module(new_module)
  File "<frozen importlib._bootstrap_external>", line 678, in exec_module
  File "<frozen importlib._bootstrap>", line 219, in _call_with_frames_removed
  File "/opt/airflow/dags/mining_etl.py", line 5, in <module>
    import data_processing
ModuleNotFoundError: No module named 'data_processing'
[2023-04-15 23:39:14,833] {processor.py:625} WARNING - No viable dags retrieved from /opt/airflow/dags/mining_etl.py
[2023-04-15 23:39:14,875] {processor.py:170} INFO - Processing /opt/airflow/dags/mining_etl.py took 0.060 seconds
[2023-04-15 23:39:44,955] {processor.py:162} INFO - Started process (PID=143) to work on /opt/airflow/dags/mining_etl.py
[2023-04-15 23:39:44,957] {processor.py:613} INFO - Processing file /opt/airflow/dags/mining_etl.py for tasks to queue
[2023-04-15 23:39:44,958] {logging_mixin.py:109} INFO - [2023-04-15 23:39:44,958] {dagbag.py:496} INFO - Filling up the DagBag from /opt/airflow/dags/mining_etl.py
[2023-04-15 23:39:44,961] {logging_mixin.py:109} INFO - [2023-04-15 23:39:44,959] {dagbag.py:329} ERROR - Failed to import: /opt/airflow/dags/mining_etl.py
Traceback (most recent call last):
  File "/home/airflow/.local/lib/python3.6/site-packages/airflow/models/dagbag.py", line 326, in _load_modules_from_file
    loader.exec_module(new_module)
  File "<frozen importlib._bootstrap_external>", line 678, in exec_module
  File "<frozen importlib._bootstrap>", line 219, in _call_with_frames_removed
  File "/opt/airflow/dags/mining_etl.py", line 5, in <module>
    import data_processing
ModuleNotFoundError: No module named 'data_processing'
[2023-04-15 23:39:44,961] {processor.py:625} WARNING - No viable dags retrieved from /opt/airflow/dags/mining_etl.py
[2023-04-15 23:39:44,994] {processor.py:170} INFO - Processing /opt/airflow/dags/mining_etl.py took 0.042 seconds
[2023-04-15 23:40:15,111] {processor.py:162} INFO - Started process (PID=144) to work on /opt/airflow/dags/mining_etl.py
[2023-04-15 23:40:15,112] {processor.py:613} INFO - Processing file /opt/airflow/dags/mining_etl.py for tasks to queue
[2023-04-15 23:40:15,113] {logging_mixin.py:109} INFO - [2023-04-15 23:40:15,113] {dagbag.py:496} INFO - Filling up the DagBag from /opt/airflow/dags/mining_etl.py
[2023-04-15 23:40:15,116] {logging_mixin.py:109} INFO - [2023-04-15 23:40:15,115] {dagbag.py:329} ERROR - Failed to import: /opt/airflow/dags/mining_etl.py
Traceback (most recent call last):
  File "/home/airflow/.local/lib/python3.6/site-packages/airflow/models/dagbag.py", line 326, in _load_modules_from_file
    loader.exec_module(new_module)
  File "<frozen importlib._bootstrap_external>", line 678, in exec_module
  File "<frozen importlib._bootstrap>", line 219, in _call_with_frames_removed
  File "/opt/airflow/dags/mining_etl.py", line 5, in <module>
    import data_processing
ModuleNotFoundError: No module named 'data_processing'
[2023-04-15 23:40:15,117] {processor.py:625} WARNING - No viable dags retrieved from /opt/airflow/dags/mining_etl.py
[2023-04-15 23:40:15,171] {processor.py:170} INFO - Processing /opt/airflow/dags/mining_etl.py took 0.063 seconds
[2023-04-15 23:40:45,268] {processor.py:162} INFO - Started process (PID=145) to work on /opt/airflow/dags/mining_etl.py
[2023-04-15 23:40:45,272] {processor.py:613} INFO - Processing file /opt/airflow/dags/mining_etl.py for tasks to queue
[2023-04-15 23:40:45,274] {logging_mixin.py:109} INFO - [2023-04-15 23:40:45,274] {dagbag.py:496} INFO - Filling up the DagBag from /opt/airflow/dags/mining_etl.py
[2023-04-15 23:40:45,279] {logging_mixin.py:109} INFO - [2023-04-15 23:40:45,278] {dagbag.py:329} ERROR - Failed to import: /opt/airflow/dags/mining_etl.py
Traceback (most recent call last):
  File "/home/airflow/.local/lib/python3.6/site-packages/airflow/models/dagbag.py", line 326, in _load_modules_from_file
    loader.exec_module(new_module)
  File "<frozen importlib._bootstrap_external>", line 678, in exec_module
  File "<frozen importlib._bootstrap>", line 219, in _call_with_frames_removed
  File "/opt/airflow/dags/mining_etl.py", line 5, in <module>
    import data_processing
ModuleNotFoundError: No module named 'data_processing'
[2023-04-15 23:40:45,280] {processor.py:625} WARNING - No viable dags retrieved from /opt/airflow/dags/mining_etl.py
[2023-04-15 23:40:45,332] {processor.py:170} INFO - Processing /opt/airflow/dags/mining_etl.py took 0.078 seconds
[2023-04-15 23:41:15,366] {processor.py:162} INFO - Started process (PID=146) to work on /opt/airflow/dags/mining_etl.py
[2023-04-15 23:41:15,367] {processor.py:613} INFO - Processing file /opt/airflow/dags/mining_etl.py for tasks to queue
[2023-04-15 23:41:15,368] {logging_mixin.py:109} INFO - [2023-04-15 23:41:15,367] {dagbag.py:496} INFO - Filling up the DagBag from /opt/airflow/dags/mining_etl.py
[2023-04-15 23:41:15,370] {logging_mixin.py:109} INFO - [2023-04-15 23:41:15,369] {dagbag.py:329} ERROR - Failed to import: /opt/airflow/dags/mining_etl.py
Traceback (most recent call last):
  File "/home/airflow/.local/lib/python3.6/site-packages/airflow/models/dagbag.py", line 326, in _load_modules_from_file
    loader.exec_module(new_module)
  File "<frozen importlib._bootstrap_external>", line 678, in exec_module
  File "<frozen importlib._bootstrap>", line 219, in _call_with_frames_removed
  File "/opt/airflow/dags/mining_etl.py", line 5, in <module>
    import data_processing
ModuleNotFoundError: No module named 'data_processing'
[2023-04-15 23:41:15,370] {processor.py:625} WARNING - No viable dags retrieved from /opt/airflow/dags/mining_etl.py
[2023-04-15 23:41:15,438] {processor.py:170} INFO - Processing /opt/airflow/dags/mining_etl.py took 0.076 seconds
[2023-04-15 23:41:45,534] {processor.py:162} INFO - Started process (PID=147) to work on /opt/airflow/dags/mining_etl.py
[2023-04-15 23:41:45,537] {processor.py:613} INFO - Processing file /opt/airflow/dags/mining_etl.py for tasks to queue
[2023-04-15 23:41:45,537] {logging_mixin.py:109} INFO - [2023-04-15 23:41:45,537] {dagbag.py:496} INFO - Filling up the DagBag from /opt/airflow/dags/mining_etl.py
[2023-04-15 23:41:45,540] {logging_mixin.py:109} INFO - [2023-04-15 23:41:45,539] {dagbag.py:329} ERROR - Failed to import: /opt/airflow/dags/mining_etl.py
Traceback (most recent call last):
  File "/home/airflow/.local/lib/python3.6/site-packages/airflow/models/dagbag.py", line 326, in _load_modules_from_file
    loader.exec_module(new_module)
  File "<frozen importlib._bootstrap_external>", line 678, in exec_module
  File "<frozen importlib._bootstrap>", line 219, in _call_with_frames_removed
  File "/opt/airflow/dags/mining_etl.py", line 5, in <module>
    import data_processing
ModuleNotFoundError: No module named 'data_processing'
[2023-04-15 23:41:45,540] {processor.py:625} WARNING - No viable dags retrieved from /opt/airflow/dags/mining_etl.py
[2023-04-15 23:41:45,591] {processor.py:170} INFO - Processing /opt/airflow/dags/mining_etl.py took 0.061 seconds
[2023-04-15 23:42:15,697] {processor.py:162} INFO - Started process (PID=148) to work on /opt/airflow/dags/mining_etl.py
[2023-04-15 23:42:15,699] {processor.py:613} INFO - Processing file /opt/airflow/dags/mining_etl.py for tasks to queue
[2023-04-15 23:42:15,700] {logging_mixin.py:109} INFO - [2023-04-15 23:42:15,700] {dagbag.py:496} INFO - Filling up the DagBag from /opt/airflow/dags/mining_etl.py
[2023-04-15 23:42:15,706] {logging_mixin.py:109} INFO - [2023-04-15 23:42:15,704] {dagbag.py:329} ERROR - Failed to import: /opt/airflow/dags/mining_etl.py
Traceback (most recent call last):
  File "/home/airflow/.local/lib/python3.6/site-packages/airflow/models/dagbag.py", line 326, in _load_modules_from_file
    loader.exec_module(new_module)
  File "<frozen importlib._bootstrap_external>", line 678, in exec_module
  File "<frozen importlib._bootstrap>", line 219, in _call_with_frames_removed
  File "/opt/airflow/dags/mining_etl.py", line 5, in <module>
    import data_processing
ModuleNotFoundError: No module named 'data_processing'
[2023-04-15 23:42:15,707] {processor.py:625} WARNING - No viable dags retrieved from /opt/airflow/dags/mining_etl.py
[2023-04-15 23:42:15,762] {processor.py:170} INFO - Processing /opt/airflow/dags/mining_etl.py took 0.076 seconds
[2023-04-15 23:42:45,813] {processor.py:162} INFO - Started process (PID=149) to work on /opt/airflow/dags/mining_etl.py
[2023-04-15 23:42:45,814] {processor.py:613} INFO - Processing file /opt/airflow/dags/mining_etl.py for tasks to queue
[2023-04-15 23:42:45,815] {logging_mixin.py:109} INFO - [2023-04-15 23:42:45,815] {dagbag.py:496} INFO - Filling up the DagBag from /opt/airflow/dags/mining_etl.py
[2023-04-15 23:42:45,821] {logging_mixin.py:109} INFO - [2023-04-15 23:42:45,819] {dagbag.py:329} ERROR - Failed to import: /opt/airflow/dags/mining_etl.py
Traceback (most recent call last):
  File "/home/airflow/.local/lib/python3.6/site-packages/airflow/models/dagbag.py", line 326, in _load_modules_from_file
    loader.exec_module(new_module)
  File "<frozen importlib._bootstrap_external>", line 678, in exec_module
  File "<frozen importlib._bootstrap>", line 219, in _call_with_frames_removed
  File "/opt/airflow/dags/mining_etl.py", line 5, in <module>
    import data_processing
ModuleNotFoundError: No module named 'data_processing'
[2023-04-15 23:42:45,821] {processor.py:625} WARNING - No viable dags retrieved from /opt/airflow/dags/mining_etl.py
[2023-04-15 23:42:45,858] {processor.py:170} INFO - Processing /opt/airflow/dags/mining_etl.py took 0.049 seconds
[2023-04-15 23:43:07,950] {processor.py:162} INFO - Started process (PID=150) to work on /opt/airflow/dags/mining_etl.py
[2023-04-15 23:43:07,957] {processor.py:613} INFO - Processing file /opt/airflow/dags/mining_etl.py for tasks to queue
[2023-04-15 23:43:07,958] {logging_mixin.py:109} INFO - [2023-04-15 23:43:07,957] {dagbag.py:496} INFO - Filling up the DagBag from /opt/airflow/dags/mining_etl.py
[2023-04-15 23:43:09,322] {logging_mixin.py:109} INFO - [2023-04-15 23:43:09,320] {dagbag.py:329} ERROR - Failed to import: /opt/airflow/dags/mining_etl.py
Traceback (most recent call last):
  File "/home/airflow/.local/lib/python3.6/site-packages/airflow/models/dagbag.py", line 326, in _load_modules_from_file
    loader.exec_module(new_module)
  File "<frozen importlib._bootstrap_external>", line 678, in exec_module
  File "<frozen importlib._bootstrap>", line 219, in _call_with_frames_removed
  File "/opt/airflow/dags/mining_etl.py", line 34, in <module>
    from airflow.operators.bash_operator import PythonOperator
ImportError: cannot import name 'PythonOperator'
[2023-04-15 23:43:09,322] {processor.py:625} WARNING - No viable dags retrieved from /opt/airflow/dags/mining_etl.py
[2023-04-15 23:43:09,366] {processor.py:170} INFO - Processing /opt/airflow/dags/mining_etl.py took 1.430 seconds
[2023-04-15 23:43:15,978] {processor.py:162} INFO - Started process (PID=154) to work on /opt/airflow/dags/mining_etl.py
[2023-04-15 23:43:15,979] {processor.py:613} INFO - Processing file /opt/airflow/dags/mining_etl.py for tasks to queue
[2023-04-15 23:43:15,980] {logging_mixin.py:109} INFO - [2023-04-15 23:43:15,980] {dagbag.py:496} INFO - Filling up the DagBag from /opt/airflow/dags/mining_etl.py
[2023-04-15 23:43:16,463] {logging_mixin.py:109} INFO - [2023-04-15 23:43:16,461] {dagbag.py:329} ERROR - Failed to import: /opt/airflow/dags/mining_etl.py
Traceback (most recent call last):
  File "/home/airflow/.local/lib/python3.6/site-packages/airflow/models/dagbag.py", line 326, in _load_modules_from_file
    loader.exec_module(new_module)
  File "<frozen importlib._bootstrap_external>", line 678, in exec_module
  File "<frozen importlib._bootstrap>", line 219, in _call_with_frames_removed
  File "/opt/airflow/dags/mining_etl.py", line 34, in <module>
    from airflow.operators.bash_operator import PythonOperator
ImportError: cannot import name 'PythonOperator'
[2023-04-15 23:43:16,463] {processor.py:625} WARNING - No viable dags retrieved from /opt/airflow/dags/mining_etl.py
[2023-04-15 23:43:16,502] {processor.py:170} INFO - Processing /opt/airflow/dags/mining_etl.py took 0.527 seconds
[2023-04-15 23:43:46,583] {processor.py:162} INFO - Started process (PID=158) to work on /opt/airflow/dags/mining_etl.py
[2023-04-15 23:43:46,611] {processor.py:613} INFO - Processing file /opt/airflow/dags/mining_etl.py for tasks to queue
[2023-04-15 23:43:46,613] {logging_mixin.py:109} INFO - [2023-04-15 23:43:46,613] {dagbag.py:496} INFO - Filling up the DagBag from /opt/airflow/dags/mining_etl.py
[2023-04-15 23:43:47,105] {logging_mixin.py:109} INFO - [2023-04-15 23:43:47,103] {dagbag.py:329} ERROR - Failed to import: /opt/airflow/dags/mining_etl.py
Traceback (most recent call last):
  File "/home/airflow/.local/lib/python3.6/site-packages/airflow/models/dagbag.py", line 326, in _load_modules_from_file
    loader.exec_module(new_module)
  File "<frozen importlib._bootstrap_external>", line 678, in exec_module
  File "<frozen importlib._bootstrap>", line 219, in _call_with_frames_removed
  File "/opt/airflow/dags/mining_etl.py", line 34, in <module>
    from airflow.operators.bash_operator import PythonOperator
ImportError: cannot import name 'PythonOperator'
[2023-04-15 23:43:47,105] {processor.py:625} WARNING - No viable dags retrieved from /opt/airflow/dags/mining_etl.py
[2023-04-15 23:43:47,145] {processor.py:170} INFO - Processing /opt/airflow/dags/mining_etl.py took 0.566 seconds
[2023-04-15 23:44:16,233] {processor.py:162} INFO - Started process (PID=162) to work on /opt/airflow/dags/mining_etl.py
[2023-04-15 23:44:16,235] {processor.py:613} INFO - Processing file /opt/airflow/dags/mining_etl.py for tasks to queue
[2023-04-15 23:44:16,236] {logging_mixin.py:109} INFO - [2023-04-15 23:44:16,236] {dagbag.py:496} INFO - Filling up the DagBag from /opt/airflow/dags/mining_etl.py
[2023-04-15 23:44:16,760] {logging_mixin.py:109} INFO - [2023-04-15 23:44:16,758] {dagbag.py:329} ERROR - Failed to import: /opt/airflow/dags/mining_etl.py
Traceback (most recent call last):
  File "/home/airflow/.local/lib/python3.6/site-packages/airflow/models/dagbag.py", line 326, in _load_modules_from_file
    loader.exec_module(new_module)
  File "<frozen importlib._bootstrap_external>", line 678, in exec_module
  File "<frozen importlib._bootstrap>", line 219, in _call_with_frames_removed
  File "/opt/airflow/dags/mining_etl.py", line 46, in <module>
    dag = 'processing_dag'
  File "/home/airflow/.local/lib/python3.6/site-packages/airflow/models/baseoperator.py", line 144, in apply_defaults
    dag_args = copy.copy(dag.default_args) or {}
AttributeError: 'str' object has no attribute 'default_args'
[2023-04-15 23:44:16,761] {processor.py:625} WARNING - No viable dags retrieved from /opt/airflow/dags/mining_etl.py
[2023-04-15 23:44:16,800] {processor.py:170} INFO - Processing /opt/airflow/dags/mining_etl.py took 0.571 seconds
[2023-04-15 23:44:46,923] {processor.py:162} INFO - Started process (PID=166) to work on /opt/airflow/dags/mining_etl.py
[2023-04-15 23:44:46,943] {processor.py:613} INFO - Processing file /opt/airflow/dags/mining_etl.py for tasks to queue
[2023-04-15 23:44:46,945] {logging_mixin.py:109} INFO - [2023-04-15 23:44:46,945] {dagbag.py:496} INFO - Filling up the DagBag from /opt/airflow/dags/mining_etl.py
[2023-04-15 23:44:47,411] {logging_mixin.py:109} INFO - [2023-04-15 23:44:47,410] {dagbag.py:329} ERROR - Failed to import: /opt/airflow/dags/mining_etl.py
Traceback (most recent call last):
  File "/home/airflow/.local/lib/python3.6/site-packages/airflow/models/dagbag.py", line 326, in _load_modules_from_file
    loader.exec_module(new_module)
  File "<frozen importlib._bootstrap_external>", line 678, in exec_module
  File "<frozen importlib._bootstrap>", line 219, in _call_with_frames_removed
  File "/opt/airflow/dags/mining_etl.py", line 46, in <module>
    dag = 'processing_dag'
  File "/home/airflow/.local/lib/python3.6/site-packages/airflow/models/baseoperator.py", line 144, in apply_defaults
    dag_args = copy.copy(dag.default_args) or {}
AttributeError: 'str' object has no attribute 'default_args'
[2023-04-15 23:44:47,412] {processor.py:625} WARNING - No viable dags retrieved from /opt/airflow/dags/mining_etl.py
[2023-04-15 23:44:47,445] {processor.py:170} INFO - Processing /opt/airflow/dags/mining_etl.py took 0.537 seconds
[2023-04-15 23:45:17,538] {processor.py:162} INFO - Started process (PID=170) to work on /opt/airflow/dags/mining_etl.py
[2023-04-15 23:45:17,539] {processor.py:613} INFO - Processing file /opt/airflow/dags/mining_etl.py for tasks to queue
[2023-04-15 23:45:17,540] {logging_mixin.py:109} INFO - [2023-04-15 23:45:17,540] {dagbag.py:496} INFO - Filling up the DagBag from /opt/airflow/dags/mining_etl.py
[2023-04-15 23:45:18,029] {logging_mixin.py:109} INFO - [2023-04-15 23:45:18,027] {dagbag.py:329} ERROR - Failed to import: /opt/airflow/dags/mining_etl.py
Traceback (most recent call last):
  File "/home/airflow/.local/lib/python3.6/site-packages/airflow/models/dagbag.py", line 326, in _load_modules_from_file
    loader.exec_module(new_module)
  File "<frozen importlib._bootstrap_external>", line 678, in exec_module
  File "<frozen importlib._bootstrap>", line 219, in _call_with_frames_removed
  File "/opt/airflow/dags/mining_etl.py", line 46, in <module>
    dag = 'processing_dag'
  File "/home/airflow/.local/lib/python3.6/site-packages/airflow/models/baseoperator.py", line 144, in apply_defaults
    dag_args = copy.copy(dag.default_args) or {}
AttributeError: 'str' object has no attribute 'default_args'
[2023-04-15 23:45:18,029] {processor.py:625} WARNING - No viable dags retrieved from /opt/airflow/dags/mining_etl.py
[2023-04-15 23:45:18,074] {processor.py:170} INFO - Processing /opt/airflow/dags/mining_etl.py took 0.540 seconds
[2023-04-15 23:45:48,132] {processor.py:162} INFO - Started process (PID=174) to work on /opt/airflow/dags/mining_etl.py
[2023-04-15 23:45:48,142] {processor.py:613} INFO - Processing file /opt/airflow/dags/mining_etl.py for tasks to queue
[2023-04-15 23:45:48,145] {logging_mixin.py:109} INFO - [2023-04-15 23:45:48,145] {dagbag.py:496} INFO - Filling up the DagBag from /opt/airflow/dags/mining_etl.py
[2023-04-15 23:45:48,632] {logging_mixin.py:109} INFO - [2023-04-15 23:45:48,630] {dagbag.py:329} ERROR - Failed to import: /opt/airflow/dags/mining_etl.py
Traceback (most recent call last):
  File "/home/airflow/.local/lib/python3.6/site-packages/airflow/models/dagbag.py", line 326, in _load_modules_from_file
    loader.exec_module(new_module)
  File "<frozen importlib._bootstrap_external>", line 678, in exec_module
  File "<frozen importlib._bootstrap>", line 219, in _call_with_frames_removed
  File "/opt/airflow/dags/mining_etl.py", line 46, in <module>
    dag = 'processing_dag'
  File "/home/airflow/.local/lib/python3.6/site-packages/airflow/models/baseoperator.py", line 144, in apply_defaults
    dag_args = copy.copy(dag.default_args) or {}
AttributeError: 'str' object has no attribute 'default_args'
[2023-04-15 23:45:48,633] {processor.py:625} WARNING - No viable dags retrieved from /opt/airflow/dags/mining_etl.py
[2023-04-15 23:45:48,668] {processor.py:170} INFO - Processing /opt/airflow/dags/mining_etl.py took 0.539 seconds
[2023-04-15 23:46:18,775] {processor.py:162} INFO - Started process (PID=178) to work on /opt/airflow/dags/mining_etl.py
[2023-04-15 23:46:18,777] {processor.py:613} INFO - Processing file /opt/airflow/dags/mining_etl.py for tasks to queue
[2023-04-15 23:46:18,778] {logging_mixin.py:109} INFO - [2023-04-15 23:46:18,778] {dagbag.py:496} INFO - Filling up the DagBag from /opt/airflow/dags/mining_etl.py
[2023-04-15 23:46:19,278] {logging_mixin.py:109} INFO - [2023-04-15 23:46:19,276] {dagbag.py:329} ERROR - Failed to import: /opt/airflow/dags/mining_etl.py
Traceback (most recent call last):
  File "/home/airflow/.local/lib/python3.6/site-packages/airflow/models/dagbag.py", line 326, in _load_modules_from_file
    loader.exec_module(new_module)
  File "<frozen importlib._bootstrap_external>", line 678, in exec_module
  File "<frozen importlib._bootstrap>", line 219, in _call_with_frames_removed
  File "/opt/airflow/dags/mining_etl.py", line 46, in <module>
    dag = 'processing_dag'
  File "/home/airflow/.local/lib/python3.6/site-packages/airflow/models/baseoperator.py", line 144, in apply_defaults
    dag_args = copy.copy(dag.default_args) or {}
AttributeError: 'str' object has no attribute 'default_args'
[2023-04-15 23:46:19,278] {processor.py:625} WARNING - No viable dags retrieved from /opt/airflow/dags/mining_etl.py
[2023-04-15 23:46:19,321] {processor.py:170} INFO - Processing /opt/airflow/dags/mining_etl.py took 0.551 seconds
[2023-04-15 23:46:33,346] {processor.py:162} INFO - Started process (PID=182) to work on /opt/airflow/dags/mining_etl.py
[2023-04-15 23:46:33,347] {processor.py:613} INFO - Processing file /opt/airflow/dags/mining_etl.py for tasks to queue
[2023-04-15 23:46:33,348] {logging_mixin.py:109} INFO - [2023-04-15 23:46:33,348] {dagbag.py:496} INFO - Filling up the DagBag from /opt/airflow/dags/mining_etl.py
[2023-04-15 23:46:33,872] {logging_mixin.py:109} INFO - [2023-04-15 23:46:33,871] {dagbag.py:329} ERROR - Failed to import: /opt/airflow/dags/mining_etl.py
Traceback (most recent call last):
  File "/home/airflow/.local/lib/python3.6/site-packages/airflow/models/dagbag.py", line 326, in _load_modules_from_file
    loader.exec_module(new_module)
  File "<frozen importlib._bootstrap_external>", line 678, in exec_module
  File "<frozen importlib._bootstrap>", line 219, in _call_with_frames_removed
  File "/opt/airflow/dags/mining_etl.py", line 46, in <module>
    dag = 'processing_dag'
  File "/home/airflow/.local/lib/python3.6/site-packages/airflow/models/baseoperator.py", line 144, in apply_defaults
    dag_args = copy.copy(dag.default_args) or {}
AttributeError: 'str' object has no attribute 'default_args'
[2023-04-15 23:46:33,873] {processor.py:625} WARNING - No viable dags retrieved from /opt/airflow/dags/mining_etl.py
[2023-04-15 23:46:33,911] {processor.py:170} INFO - Processing /opt/airflow/dags/mining_etl.py took 0.570 seconds
[2023-04-15 23:47:03,996] {processor.py:162} INFO - Started process (PID=186) to work on /opt/airflow/dags/mining_etl.py
[2023-04-15 23:47:04,003] {processor.py:613} INFO - Processing file /opt/airflow/dags/mining_etl.py for tasks to queue
[2023-04-15 23:47:04,004] {logging_mixin.py:109} INFO - [2023-04-15 23:47:04,004] {dagbag.py:496} INFO - Filling up the DagBag from /opt/airflow/dags/mining_etl.py
[2023-04-15 23:47:04,522] {logging_mixin.py:109} INFO - [2023-04-15 23:47:04,520] {dagbag.py:329} ERROR - Failed to import: /opt/airflow/dags/mining_etl.py
Traceback (most recent call last):
  File "/home/airflow/.local/lib/python3.6/site-packages/airflow/models/dagbag.py", line 326, in _load_modules_from_file
    loader.exec_module(new_module)
  File "<frozen importlib._bootstrap_external>", line 678, in exec_module
  File "<frozen importlib._bootstrap>", line 219, in _call_with_frames_removed
  File "/opt/airflow/dags/mining_etl.py", line 46, in <module>
    dag = 'processing_dag'
  File "/home/airflow/.local/lib/python3.6/site-packages/airflow/models/baseoperator.py", line 144, in apply_defaults
    dag_args = copy.copy(dag.default_args) or {}
AttributeError: 'str' object has no attribute 'default_args'
[2023-04-15 23:47:04,522] {processor.py:625} WARNING - No viable dags retrieved from /opt/airflow/dags/mining_etl.py
[2023-04-15 23:47:04,580] {processor.py:170} INFO - Processing /opt/airflow/dags/mining_etl.py took 0.589 seconds
[2023-04-15 23:47:34,639] {processor.py:162} INFO - Started process (PID=190) to work on /opt/airflow/dags/mining_etl.py
[2023-04-15 23:47:34,642] {processor.py:613} INFO - Processing file /opt/airflow/dags/mining_etl.py for tasks to queue
[2023-04-15 23:47:34,643] {logging_mixin.py:109} INFO - [2023-04-15 23:47:34,643] {dagbag.py:496} INFO - Filling up the DagBag from /opt/airflow/dags/mining_etl.py
[2023-04-15 23:47:35,087] {logging_mixin.py:109} INFO - [2023-04-15 23:47:35,085] {dagbag.py:329} ERROR - Failed to import: /opt/airflow/dags/mining_etl.py
Traceback (most recent call last):
  File "/home/airflow/.local/lib/python3.6/site-packages/airflow/models/dagbag.py", line 326, in _load_modules_from_file
    loader.exec_module(new_module)
  File "<frozen importlib._bootstrap_external>", line 678, in exec_module
  File "<frozen importlib._bootstrap>", line 219, in _call_with_frames_removed
  File "/opt/airflow/dags/mining_etl.py", line 46, in <module>
    dag = 'processing_dag'
  File "/home/airflow/.local/lib/python3.6/site-packages/airflow/models/baseoperator.py", line 144, in apply_defaults
    dag_args = copy.copy(dag.default_args) or {}
AttributeError: 'str' object has no attribute 'default_args'
[2023-04-15 23:47:35,087] {processor.py:625} WARNING - No viable dags retrieved from /opt/airflow/dags/mining_etl.py
[2023-04-15 23:47:35,126] {processor.py:170} INFO - Processing /opt/airflow/dags/mining_etl.py took 0.500 seconds
[2023-04-15 23:47:55,212] {processor.py:162} INFO - Started process (PID=194) to work on /opt/airflow/dags/mining_etl.py
[2023-04-15 23:47:55,215] {processor.py:613} INFO - Processing file /opt/airflow/dags/mining_etl.py for tasks to queue
[2023-04-15 23:47:55,219] {logging_mixin.py:109} INFO - [2023-04-15 23:47:55,218] {dagbag.py:496} INFO - Filling up the DagBag from /opt/airflow/dags/mining_etl.py
[2023-04-15 23:47:55,672] {logging_mixin.py:109} INFO - [2023-04-15 23:47:55,671] {dagbag.py:329} ERROR - Failed to import: /opt/airflow/dags/mining_etl.py
Traceback (most recent call last):
  File "/home/airflow/.local/lib/python3.6/site-packages/airflow/models/dagbag.py", line 326, in _load_modules_from_file
    loader.exec_module(new_module)
  File "<frozen importlib._bootstrap_external>", line 678, in exec_module
  File "<frozen importlib._bootstrap>", line 219, in _call_with_frames_removed
  File "/opt/airflow/dags/mining_etl.py", line 46, in <module>
    dag = 'processing_dag'
  File "/home/airflow/.local/lib/python3.6/site-packages/airflow/models/baseoperator.py", line 144, in apply_defaults
    dag_args = copy.copy(dag.default_args) or {}
AttributeError: 'str' object has no attribute 'default_args'
[2023-04-15 23:47:55,673] {processor.py:625} WARNING - No viable dags retrieved from /opt/airflow/dags/mining_etl.py
[2023-04-15 23:47:55,752] {processor.py:170} INFO - Processing /opt/airflow/dags/mining_etl.py took 0.553 seconds
[2023-04-15 23:47:57,739] {processor.py:162} INFO - Started process (PID=198) to work on /opt/airflow/dags/mining_etl.py
[2023-04-15 23:47:57,740] {processor.py:613} INFO - Processing file /opt/airflow/dags/mining_etl.py for tasks to queue
[2023-04-15 23:47:57,740] {logging_mixin.py:109} INFO - [2023-04-15 23:47:57,740] {dagbag.py:496} INFO - Filling up the DagBag from /opt/airflow/dags/mining_etl.py
[2023-04-15 23:47:58,229] {logging_mixin.py:109} INFO - [2023-04-15 23:47:58,228] {dagbag.py:329} ERROR - Failed to import: /opt/airflow/dags/mining_etl.py
Traceback (most recent call last):
  File "/home/airflow/.local/lib/python3.6/site-packages/airflow/models/dagbag.py", line 326, in _load_modules_from_file
    loader.exec_module(new_module)
  File "<frozen importlib._bootstrap_external>", line 678, in exec_module
  File "<frozen importlib._bootstrap>", line 219, in _call_with_frames_removed
  File "/opt/airflow/dags/mining_etl.py", line 46, in <module>
    dag = 'processing_dag'
  File "/home/airflow/.local/lib/python3.6/site-packages/airflow/models/baseoperator.py", line 144, in apply_defaults
    dag_args = copy.copy(dag.default_args) or {}
AttributeError: 'str' object has no attribute 'default_args'
[2023-04-15 23:47:58,230] {processor.py:625} WARNING - No viable dags retrieved from /opt/airflow/dags/mining_etl.py
[2023-04-15 23:47:58,303] {processor.py:170} INFO - Processing /opt/airflow/dags/mining_etl.py took 0.568 seconds
[2023-04-15 23:48:28,416] {processor.py:162} INFO - Started process (PID=202) to work on /opt/airflow/dags/mining_etl.py
[2023-04-15 23:48:28,446] {processor.py:613} INFO - Processing file /opt/airflow/dags/mining_etl.py for tasks to queue
[2023-04-15 23:48:28,446] {logging_mixin.py:109} INFO - [2023-04-15 23:48:28,446] {dagbag.py:496} INFO - Filling up the DagBag from /opt/airflow/dags/mining_etl.py
[2023-04-15 23:48:28,919] {logging_mixin.py:109} INFO - [2023-04-15 23:48:28,918] {dagbag.py:329} ERROR - Failed to import: /opt/airflow/dags/mining_etl.py
Traceback (most recent call last):
  File "/home/airflow/.local/lib/python3.6/site-packages/airflow/models/dagbag.py", line 326, in _load_modules_from_file
    loader.exec_module(new_module)
  File "<frozen importlib._bootstrap_external>", line 678, in exec_module
  File "<frozen importlib._bootstrap>", line 219, in _call_with_frames_removed
  File "/opt/airflow/dags/mining_etl.py", line 46, in <module>
    dag = 'processing_dag'
  File "/home/airflow/.local/lib/python3.6/site-packages/airflow/models/baseoperator.py", line 144, in apply_defaults
    dag_args = copy.copy(dag.default_args) or {}
AttributeError: 'str' object has no attribute 'default_args'
[2023-04-15 23:48:28,920] {processor.py:625} WARNING - No viable dags retrieved from /opt/airflow/dags/mining_etl.py
[2023-04-15 23:48:28,963] {processor.py:170} INFO - Processing /opt/airflow/dags/mining_etl.py took 0.557 seconds
[2023-04-15 23:48:59,043] {processor.py:162} INFO - Started process (PID=206) to work on /opt/airflow/dags/mining_etl.py
[2023-04-15 23:48:59,051] {processor.py:613} INFO - Processing file /opt/airflow/dags/mining_etl.py for tasks to queue
[2023-04-15 23:48:59,054] {logging_mixin.py:109} INFO - [2023-04-15 23:48:59,053] {dagbag.py:496} INFO - Filling up the DagBag from /opt/airflow/dags/mining_etl.py
[2023-04-15 23:48:59,485] {logging_mixin.py:109} INFO - [2023-04-15 23:48:59,484] {dagbag.py:329} ERROR - Failed to import: /opt/airflow/dags/mining_etl.py
Traceback (most recent call last):
  File "/home/airflow/.local/lib/python3.6/site-packages/airflow/models/dagbag.py", line 326, in _load_modules_from_file
    loader.exec_module(new_module)
  File "<frozen importlib._bootstrap_external>", line 678, in exec_module
  File "<frozen importlib._bootstrap>", line 219, in _call_with_frames_removed
  File "/opt/airflow/dags/mining_etl.py", line 46, in <module>
    dag = 'processing_dag'
  File "/home/airflow/.local/lib/python3.6/site-packages/airflow/models/baseoperator.py", line 144, in apply_defaults
    dag_args = copy.copy(dag.default_args) or {}
AttributeError: 'str' object has no attribute 'default_args'
[2023-04-15 23:48:59,486] {processor.py:625} WARNING - No viable dags retrieved from /opt/airflow/dags/mining_etl.py
[2023-04-15 23:48:59,518] {processor.py:170} INFO - Processing /opt/airflow/dags/mining_etl.py took 0.488 seconds
[2023-04-15 23:49:29,621] {processor.py:162} INFO - Started process (PID=210) to work on /opt/airflow/dags/mining_etl.py
[2023-04-15 23:49:29,649] {processor.py:613} INFO - Processing file /opt/airflow/dags/mining_etl.py for tasks to queue
[2023-04-15 23:49:29,651] {logging_mixin.py:109} INFO - [2023-04-15 23:49:29,650] {dagbag.py:496} INFO - Filling up the DagBag from /opt/airflow/dags/mining_etl.py
[2023-04-15 23:49:30,184] {logging_mixin.py:109} INFO - [2023-04-15 23:49:30,182] {dagbag.py:329} ERROR - Failed to import: /opt/airflow/dags/mining_etl.py
Traceback (most recent call last):
  File "/home/airflow/.local/lib/python3.6/site-packages/airflow/models/dagbag.py", line 326, in _load_modules_from_file
    loader.exec_module(new_module)
  File "<frozen importlib._bootstrap_external>", line 678, in exec_module
  File "<frozen importlib._bootstrap>", line 219, in _call_with_frames_removed
  File "/opt/airflow/dags/mining_etl.py", line 46, in <module>
    dag = 'processing_dag'
  File "/home/airflow/.local/lib/python3.6/site-packages/airflow/models/baseoperator.py", line 144, in apply_defaults
    dag_args = copy.copy(dag.default_args) or {}
AttributeError: 'str' object has no attribute 'default_args'
[2023-04-15 23:49:30,184] {processor.py:625} WARNING - No viable dags retrieved from /opt/airflow/dags/mining_etl.py
[2023-04-15 23:49:30,222] {processor.py:170} INFO - Processing /opt/airflow/dags/mining_etl.py took 0.616 seconds
[2023-04-15 23:50:00,311] {processor.py:162} INFO - Started process (PID=214) to work on /opt/airflow/dags/mining_etl.py
[2023-04-15 23:50:00,313] {processor.py:613} INFO - Processing file /opt/airflow/dags/mining_etl.py for tasks to queue
[2023-04-15 23:50:00,313] {logging_mixin.py:109} INFO - [2023-04-15 23:50:00,313] {dagbag.py:496} INFO - Filling up the DagBag from /opt/airflow/dags/mining_etl.py
[2023-04-15 23:50:00,963] {logging_mixin.py:109} INFO - [2023-04-15 23:50:00,961] {dagbag.py:329} ERROR - Failed to import: /opt/airflow/dags/mining_etl.py
Traceback (most recent call last):
  File "/home/airflow/.local/lib/python3.6/site-packages/airflow/models/dagbag.py", line 326, in _load_modules_from_file
    loader.exec_module(new_module)
  File "<frozen importlib._bootstrap_external>", line 678, in exec_module
  File "<frozen importlib._bootstrap>", line 219, in _call_with_frames_removed
  File "/opt/airflow/dags/mining_etl.py", line 46, in <module>
    dag = 'processing_dag'
  File "/home/airflow/.local/lib/python3.6/site-packages/airflow/models/baseoperator.py", line 144, in apply_defaults
    dag_args = copy.copy(dag.default_args) or {}
AttributeError: 'str' object has no attribute 'default_args'
[2023-04-15 23:50:00,963] {processor.py:625} WARNING - No viable dags retrieved from /opt/airflow/dags/mining_etl.py
[2023-04-15 23:50:01,001] {processor.py:170} INFO - Processing /opt/airflow/dags/mining_etl.py took 0.693 seconds
[2023-04-15 23:50:31,101] {processor.py:162} INFO - Started process (PID=218) to work on /opt/airflow/dags/mining_etl.py
[2023-04-15 23:50:31,117] {processor.py:613} INFO - Processing file /opt/airflow/dags/mining_etl.py for tasks to queue
[2023-04-15 23:50:31,119] {logging_mixin.py:109} INFO - [2023-04-15 23:50:31,118] {dagbag.py:496} INFO - Filling up the DagBag from /opt/airflow/dags/mining_etl.py
[2023-04-15 23:50:31,588] {logging_mixin.py:109} INFO - [2023-04-15 23:50:31,587] {dagbag.py:329} ERROR - Failed to import: /opt/airflow/dags/mining_etl.py
Traceback (most recent call last):
  File "/home/airflow/.local/lib/python3.6/site-packages/airflow/models/dagbag.py", line 326, in _load_modules_from_file
    loader.exec_module(new_module)
  File "<frozen importlib._bootstrap_external>", line 678, in exec_module
  File "<frozen importlib._bootstrap>", line 219, in _call_with_frames_removed
  File "/opt/airflow/dags/mining_etl.py", line 46, in <module>
    dag = 'processing_dag'
  File "/home/airflow/.local/lib/python3.6/site-packages/airflow/models/baseoperator.py", line 144, in apply_defaults
    dag_args = copy.copy(dag.default_args) or {}
AttributeError: 'str' object has no attribute 'default_args'
[2023-04-15 23:50:31,589] {processor.py:625} WARNING - No viable dags retrieved from /opt/airflow/dags/mining_etl.py
[2023-04-15 23:50:31,629] {processor.py:170} INFO - Processing /opt/airflow/dags/mining_etl.py took 0.539 seconds
[2023-04-15 23:51:01,728] {processor.py:162} INFO - Started process (PID=222) to work on /opt/airflow/dags/mining_etl.py
[2023-04-15 23:51:01,730] {processor.py:613} INFO - Processing file /opt/airflow/dags/mining_etl.py for tasks to queue
[2023-04-15 23:51:01,732] {logging_mixin.py:109} INFO - [2023-04-15 23:51:01,732] {dagbag.py:496} INFO - Filling up the DagBag from /opt/airflow/dags/mining_etl.py
[2023-04-15 23:51:02,157] {logging_mixin.py:109} INFO - [2023-04-15 23:51:02,155] {dagbag.py:329} ERROR - Failed to import: /opt/airflow/dags/mining_etl.py
Traceback (most recent call last):
  File "/home/airflow/.local/lib/python3.6/site-packages/airflow/models/dagbag.py", line 326, in _load_modules_from_file
    loader.exec_module(new_module)
  File "<frozen importlib._bootstrap_external>", line 678, in exec_module
  File "<frozen importlib._bootstrap>", line 219, in _call_with_frames_removed
  File "/opt/airflow/dags/mining_etl.py", line 46, in <module>
    dag = 'processing_dag'
  File "/home/airflow/.local/lib/python3.6/site-packages/airflow/models/baseoperator.py", line 144, in apply_defaults
    dag_args = copy.copy(dag.default_args) or {}
AttributeError: 'str' object has no attribute 'default_args'
[2023-04-15 23:51:02,157] {processor.py:625} WARNING - No viable dags retrieved from /opt/airflow/dags/mining_etl.py
[2023-04-15 23:51:02,191] {processor.py:170} INFO - Processing /opt/airflow/dags/mining_etl.py took 0.470 seconds
[2023-04-15 23:51:32,276] {processor.py:162} INFO - Started process (PID=226) to work on /opt/airflow/dags/mining_etl.py
[2023-04-15 23:51:32,289] {processor.py:613} INFO - Processing file /opt/airflow/dags/mining_etl.py for tasks to queue
[2023-04-15 23:51:32,290] {logging_mixin.py:109} INFO - [2023-04-15 23:51:32,290] {dagbag.py:496} INFO - Filling up the DagBag from /opt/airflow/dags/mining_etl.py
[2023-04-15 23:51:32,772] {logging_mixin.py:109} INFO - [2023-04-15 23:51:32,771] {dagbag.py:329} ERROR - Failed to import: /opt/airflow/dags/mining_etl.py
Traceback (most recent call last):
  File "/home/airflow/.local/lib/python3.6/site-packages/airflow/models/dagbag.py", line 326, in _load_modules_from_file
    loader.exec_module(new_module)
  File "<frozen importlib._bootstrap_external>", line 678, in exec_module
  File "<frozen importlib._bootstrap>", line 219, in _call_with_frames_removed
  File "/opt/airflow/dags/mining_etl.py", line 46, in <module>
    dag = 'processing_dag'
  File "/home/airflow/.local/lib/python3.6/site-packages/airflow/models/baseoperator.py", line 144, in apply_defaults
    dag_args = copy.copy(dag.default_args) or {}
AttributeError: 'str' object has no attribute 'default_args'
[2023-04-15 23:51:32,773] {processor.py:625} WARNING - No viable dags retrieved from /opt/airflow/dags/mining_etl.py
[2023-04-15 23:51:32,801] {processor.py:170} INFO - Processing /opt/airflow/dags/mining_etl.py took 0.529 seconds
[2023-04-15 23:52:02,905] {processor.py:162} INFO - Started process (PID=230) to work on /opt/airflow/dags/mining_etl.py
[2023-04-15 23:52:02,906] {processor.py:613} INFO - Processing file /opt/airflow/dags/mining_etl.py for tasks to queue
[2023-04-15 23:52:02,906] {logging_mixin.py:109} INFO - [2023-04-15 23:52:02,906] {dagbag.py:496} INFO - Filling up the DagBag from /opt/airflow/dags/mining_etl.py
[2023-04-15 23:52:03,375] {logging_mixin.py:109} INFO - [2023-04-15 23:52:03,373] {dagbag.py:329} ERROR - Failed to import: /opt/airflow/dags/mining_etl.py
Traceback (most recent call last):
  File "/home/airflow/.local/lib/python3.6/site-packages/airflow/models/dagbag.py", line 326, in _load_modules_from_file
    loader.exec_module(new_module)
  File "<frozen importlib._bootstrap_external>", line 678, in exec_module
  File "<frozen importlib._bootstrap>", line 219, in _call_with_frames_removed
  File "/opt/airflow/dags/mining_etl.py", line 46, in <module>
    dag = 'processing_dag'
  File "/home/airflow/.local/lib/python3.6/site-packages/airflow/models/baseoperator.py", line 144, in apply_defaults
    dag_args = copy.copy(dag.default_args) or {}
AttributeError: 'str' object has no attribute 'default_args'
[2023-04-15 23:52:03,375] {processor.py:625} WARNING - No viable dags retrieved from /opt/airflow/dags/mining_etl.py
[2023-04-15 23:52:03,415] {processor.py:170} INFO - Processing /opt/airflow/dags/mining_etl.py took 0.514 seconds
[2023-04-15 23:52:33,476] {processor.py:162} INFO - Started process (PID=234) to work on /opt/airflow/dags/mining_etl.py
[2023-04-15 23:52:33,494] {processor.py:613} INFO - Processing file /opt/airflow/dags/mining_etl.py for tasks to queue
[2023-04-15 23:52:33,496] {logging_mixin.py:109} INFO - [2023-04-15 23:52:33,495] {dagbag.py:496} INFO - Filling up the DagBag from /opt/airflow/dags/mining_etl.py
[2023-04-15 23:52:33,973] {logging_mixin.py:109} INFO - [2023-04-15 23:52:33,971] {dagbag.py:329} ERROR - Failed to import: /opt/airflow/dags/mining_etl.py
Traceback (most recent call last):
  File "/home/airflow/.local/lib/python3.6/site-packages/airflow/models/dagbag.py", line 326, in _load_modules_from_file
    loader.exec_module(new_module)
  File "<frozen importlib._bootstrap_external>", line 678, in exec_module
  File "<frozen importlib._bootstrap>", line 219, in _call_with_frames_removed
  File "/opt/airflow/dags/mining_etl.py", line 46, in <module>
    dag = 'processing_dag'
  File "/home/airflow/.local/lib/python3.6/site-packages/airflow/models/baseoperator.py", line 144, in apply_defaults
    dag_args = copy.copy(dag.default_args) or {}
AttributeError: 'str' object has no attribute 'default_args'
[2023-04-15 23:52:33,973] {processor.py:625} WARNING - No viable dags retrieved from /opt/airflow/dags/mining_etl.py
[2023-04-15 23:52:34,096] {processor.py:170} INFO - Processing /opt/airflow/dags/mining_etl.py took 0.651 seconds
[2023-04-15 23:53:04,207] {processor.py:162} INFO - Started process (PID=238) to work on /opt/airflow/dags/mining_etl.py
[2023-04-15 23:53:04,208] {processor.py:613} INFO - Processing file /opt/airflow/dags/mining_etl.py for tasks to queue
[2023-04-15 23:53:04,209] {logging_mixin.py:109} INFO - [2023-04-15 23:53:04,209] {dagbag.py:496} INFO - Filling up the DagBag from /opt/airflow/dags/mining_etl.py
[2023-04-15 23:53:04,700] {logging_mixin.py:109} INFO - [2023-04-15 23:53:04,698] {dagbag.py:329} ERROR - Failed to import: /opt/airflow/dags/mining_etl.py
Traceback (most recent call last):
  File "/home/airflow/.local/lib/python3.6/site-packages/airflow/models/dagbag.py", line 326, in _load_modules_from_file
    loader.exec_module(new_module)
  File "<frozen importlib._bootstrap_external>", line 678, in exec_module
  File "<frozen importlib._bootstrap>", line 219, in _call_with_frames_removed
  File "/opt/airflow/dags/mining_etl.py", line 46, in <module>
    dag = 'processing_dag'
  File "/home/airflow/.local/lib/python3.6/site-packages/airflow/models/baseoperator.py", line 144, in apply_defaults
    dag_args = copy.copy(dag.default_args) or {}
AttributeError: 'str' object has no attribute 'default_args'
[2023-04-15 23:53:04,701] {processor.py:625} WARNING - No viable dags retrieved from /opt/airflow/dags/mining_etl.py
[2023-04-15 23:53:04,738] {processor.py:170} INFO - Processing /opt/airflow/dags/mining_etl.py took 0.535 seconds
[2023-04-15 23:53:34,814] {processor.py:162} INFO - Started process (PID=242) to work on /opt/airflow/dags/mining_etl.py
[2023-04-15 23:53:34,832] {processor.py:613} INFO - Processing file /opt/airflow/dags/mining_etl.py for tasks to queue
[2023-04-15 23:53:34,833] {logging_mixin.py:109} INFO - [2023-04-15 23:53:34,833] {dagbag.py:496} INFO - Filling up the DagBag from /opt/airflow/dags/mining_etl.py
[2023-04-15 23:53:35,257] {logging_mixin.py:109} INFO - [2023-04-15 23:53:35,256] {dagbag.py:329} ERROR - Failed to import: /opt/airflow/dags/mining_etl.py
Traceback (most recent call last):
  File "/home/airflow/.local/lib/python3.6/site-packages/airflow/models/dagbag.py", line 326, in _load_modules_from_file
    loader.exec_module(new_module)
  File "<frozen importlib._bootstrap_external>", line 678, in exec_module
  File "<frozen importlib._bootstrap>", line 219, in _call_with_frames_removed
  File "/opt/airflow/dags/mining_etl.py", line 46, in <module>
    dag = 'processing_dag'
  File "/home/airflow/.local/lib/python3.6/site-packages/airflow/models/baseoperator.py", line 144, in apply_defaults
    dag_args = copy.copy(dag.default_args) or {}
AttributeError: 'str' object has no attribute 'default_args'
[2023-04-15 23:53:35,258] {processor.py:625} WARNING - No viable dags retrieved from /opt/airflow/dags/mining_etl.py
[2023-04-15 23:53:35,309] {processor.py:170} INFO - Processing /opt/airflow/dags/mining_etl.py took 0.502 seconds
[2023-04-15 23:54:00,919] {processor.py:162} INFO - Started process (PID=246) to work on /opt/airflow/dags/mining_etl.py
[2023-04-15 23:54:00,922] {processor.py:613} INFO - Processing file /opt/airflow/dags/mining_etl.py for tasks to queue
[2023-04-15 23:54:00,923] {logging_mixin.py:109} INFO - [2023-04-15 23:54:00,923] {dagbag.py:496} INFO - Filling up the DagBag from /opt/airflow/dags/mining_etl.py
[2023-04-15 23:54:01,425] {processor.py:623} INFO - DAG(s) dict_keys(['processing_dag']) retrieved from /opt/airflow/dags/mining_etl.py
[2023-04-15 23:54:06,449] {logging_mixin.py:109} INFO - [2023-04-15 23:54:06,447] {dag.py:1834} INFO - Sync 1 DAGs
[2023-04-15 23:54:06,501] {logging_mixin.py:109} INFO - [2023-04-15 23:54:06,499] {dag.py:1853} INFO - Creating ORM DAG for processing_dag
[2023-04-15 23:54:06,507] {logging_mixin.py:109} INFO - [2023-04-15 23:54:06,507] {dag.py:2287} INFO - Setting next_dagrun for processing_dag to 2023-04-15T00:00:00+00:00
[2023-04-15 23:54:06,588] {processor.py:170} INFO - Processing /opt/airflow/dags/mining_etl.py took 5.677 seconds
[2023-04-15 23:54:11,472] {processor.py:162} INFO - Started process (PID=251) to work on /opt/airflow/dags/mining_etl.py
[2023-04-15 23:54:11,473] {processor.py:613} INFO - Processing file /opt/airflow/dags/mining_etl.py for tasks to queue
[2023-04-15 23:54:11,474] {logging_mixin.py:109} INFO - [2023-04-15 23:54:11,474] {dagbag.py:496} INFO - Filling up the DagBag from /opt/airflow/dags/mining_etl.py
[2023-04-15 23:54:12,013] {processor.py:623} INFO - DAG(s) dict_keys(['processing_dag']) retrieved from /opt/airflow/dags/mining_etl.py
[2023-04-15 23:54:12,024] {logging_mixin.py:109} INFO - [2023-04-15 23:54:12,024] {dag.py:1834} INFO - Sync 1 DAGs
[2023-04-15 23:54:12,037] {logging_mixin.py:109} INFO - [2023-04-15 23:54:12,037] {dag.py:2287} INFO - Setting next_dagrun for processing_dag to 2023-04-15T00:00:00+00:00
[2023-04-15 23:54:12,067] {processor.py:170} INFO - Processing /opt/airflow/dags/mining_etl.py took 0.599 seconds
[2023-04-15 23:54:17,126] {processor.py:162} INFO - Started process (PID=255) to work on /opt/airflow/dags/mining_etl.py
[2023-04-15 23:54:17,128] {processor.py:613} INFO - Processing file /opt/airflow/dags/mining_etl.py for tasks to queue
[2023-04-15 23:54:17,128] {logging_mixin.py:109} INFO - [2023-04-15 23:54:17,128] {dagbag.py:496} INFO - Filling up the DagBag from /opt/airflow/dags/mining_etl.py
[2023-04-15 23:54:17,666] {processor.py:623} INFO - DAG(s) dict_keys(['processing_dag']) retrieved from /opt/airflow/dags/mining_etl.py
[2023-04-15 23:54:17,679] {logging_mixin.py:109} INFO - [2023-04-15 23:54:17,679] {dag.py:1834} INFO - Sync 1 DAGs
[2023-04-15 23:54:17,694] {logging_mixin.py:109} INFO - [2023-04-15 23:54:17,694] {dag.py:2287} INFO - Setting next_dagrun for processing_dag to 2023-04-15T00:00:00+00:00
[2023-04-15 23:54:17,753] {processor.py:170} INFO - Processing /opt/airflow/dags/mining_etl.py took 0.632 seconds
[2023-04-15 23:54:47,787] {processor.py:162} INFO - Started process (PID=259) to work on /opt/airflow/dags/mining_etl.py
[2023-04-15 23:54:47,805] {processor.py:613} INFO - Processing file /opt/airflow/dags/mining_etl.py for tasks to queue
[2023-04-15 23:54:47,806] {logging_mixin.py:109} INFO - [2023-04-15 23:54:47,806] {dagbag.py:496} INFO - Filling up the DagBag from /opt/airflow/dags/mining_etl.py
[2023-04-15 23:54:48,283] {processor.py:623} INFO - DAG(s) dict_keys(['processing_dag']) retrieved from /opt/airflow/dags/mining_etl.py
[2023-04-15 23:54:48,300] {logging_mixin.py:109} INFO - [2023-04-15 23:54:48,300] {dag.py:1834} INFO - Sync 1 DAGs
[2023-04-15 23:54:48,313] {logging_mixin.py:109} INFO - [2023-04-15 23:54:48,313] {dag.py:2287} INFO - Setting next_dagrun for processing_dag to 2023-04-15T00:00:00+00:00
[2023-04-15 23:54:48,339] {processor.py:170} INFO - Processing /opt/airflow/dags/mining_etl.py took 0.556 seconds
[2023-04-15 23:55:18,424] {processor.py:162} INFO - Started process (PID=263) to work on /opt/airflow/dags/mining_etl.py
[2023-04-15 23:55:18,425] {processor.py:613} INFO - Processing file /opt/airflow/dags/mining_etl.py for tasks to queue
[2023-04-15 23:55:18,426] {logging_mixin.py:109} INFO - [2023-04-15 23:55:18,426] {dagbag.py:496} INFO - Filling up the DagBag from /opt/airflow/dags/mining_etl.py
[2023-04-15 23:55:19,064] {processor.py:623} INFO - DAG(s) dict_keys(['processing_dag']) retrieved from /opt/airflow/dags/mining_etl.py
[2023-04-15 23:55:19,081] {logging_mixin.py:109} INFO - [2023-04-15 23:55:19,081] {dag.py:1834} INFO - Sync 1 DAGs
[2023-04-15 23:55:19,091] {logging_mixin.py:109} INFO - [2023-04-15 23:55:19,090] {dag.py:2287} INFO - Setting next_dagrun for processing_dag to 2023-04-15T00:00:00+00:00
[2023-04-15 23:55:19,126] {processor.py:170} INFO - Processing /opt/airflow/dags/mining_etl.py took 0.706 seconds
[2023-04-15 23:55:49,303] {processor.py:162} INFO - Started process (PID=267) to work on /opt/airflow/dags/mining_etl.py
[2023-04-15 23:55:49,313] {processor.py:613} INFO - Processing file /opt/airflow/dags/mining_etl.py for tasks to queue
[2023-04-15 23:55:49,315] {logging_mixin.py:109} INFO - [2023-04-15 23:55:49,315] {dagbag.py:496} INFO - Filling up the DagBag from /opt/airflow/dags/mining_etl.py
[2023-04-15 23:55:49,880] {processor.py:623} INFO - DAG(s) dict_keys(['processing_dag']) retrieved from /opt/airflow/dags/mining_etl.py
[2023-04-15 23:55:49,895] {logging_mixin.py:109} INFO - [2023-04-15 23:55:49,895] {dag.py:1834} INFO - Sync 1 DAGs
[2023-04-15 23:55:49,906] {logging_mixin.py:109} INFO - [2023-04-15 23:55:49,906] {dag.py:2287} INFO - Setting next_dagrun for processing_dag to 2023-04-15T00:00:00+00:00
[2023-04-15 23:55:49,946] {processor.py:170} INFO - Processing /opt/airflow/dags/mining_etl.py took 0.651 seconds
[2023-04-15 23:55:54,998] {processor.py:162} INFO - Started process (PID=271) to work on /opt/airflow/dags/mining_etl.py
[2023-04-15 23:55:55,000] {processor.py:613} INFO - Processing file /opt/airflow/dags/mining_etl.py for tasks to queue
[2023-04-15 23:55:55,001] {logging_mixin.py:109} INFO - [2023-04-15 23:55:55,000] {dagbag.py:496} INFO - Filling up the DagBag from /opt/airflow/dags/mining_etl.py
[2023-04-15 23:55:55,528] {processor.py:623} INFO - DAG(s) dict_keys(['processing_dag']) retrieved from /opt/airflow/dags/mining_etl.py
[2023-04-15 23:55:55,544] {logging_mixin.py:109} INFO - [2023-04-15 23:55:55,544] {dag.py:1834} INFO - Sync 1 DAGs
[2023-04-15 23:55:55,554] {logging_mixin.py:109} INFO - [2023-04-15 23:55:55,554] {dag.py:2287} INFO - Setting next_dagrun for processing_dag to 2023-04-15T00:00:00+00:00
[2023-04-15 23:55:55,582] {processor.py:170} INFO - Processing /opt/airflow/dags/mining_etl.py took 0.592 seconds
[2023-04-15 23:56:25,666] {processor.py:162} INFO - Started process (PID=275) to work on /opt/airflow/dags/mining_etl.py
[2023-04-15 23:56:25,670] {processor.py:613} INFO - Processing file /opt/airflow/dags/mining_etl.py for tasks to queue
[2023-04-15 23:56:25,671] {logging_mixin.py:109} INFO - [2023-04-15 23:56:25,671] {dagbag.py:496} INFO - Filling up the DagBag from /opt/airflow/dags/mining_etl.py
[2023-04-15 23:56:26,193] {processor.py:623} INFO - DAG(s) dict_keys(['processing_dag']) retrieved from /opt/airflow/dags/mining_etl.py
[2023-04-15 23:56:26,209] {logging_mixin.py:109} INFO - [2023-04-15 23:56:26,209] {dag.py:1834} INFO - Sync 1 DAGs
[2023-04-15 23:56:26,218] {logging_mixin.py:109} INFO - [2023-04-15 23:56:26,218] {dag.py:2287} INFO - Setting next_dagrun for processing_dag to 2023-04-15T00:00:00+00:00
[2023-04-15 23:56:26,244] {processor.py:170} INFO - Processing /opt/airflow/dags/mining_etl.py took 0.592 seconds
[2023-04-15 23:56:53,321] {processor.py:162} INFO - Started process (PID=279) to work on /opt/airflow/dags/mining_etl.py
[2023-04-15 23:56:53,322] {processor.py:613} INFO - Processing file /opt/airflow/dags/mining_etl.py for tasks to queue
[2023-04-15 23:56:53,323] {logging_mixin.py:109} INFO - [2023-04-15 23:56:53,323] {dagbag.py:496} INFO - Filling up the DagBag from /opt/airflow/dags/mining_etl.py
[2023-04-15 23:56:53,326] {logging_mixin.py:109} INFO - [2023-04-15 23:56:53,325] {dagbag.py:329} ERROR - Failed to import: /opt/airflow/dags/mining_etl.py
Traceback (most recent call last):
  File "/home/airflow/.local/lib/python3.6/site-packages/airflow/models/dagbag.py", line 326, in _load_modules_from_file
    loader.exec_module(new_module)
  File "<frozen importlib._bootstrap_external>", line 674, in exec_module
  File "<frozen importlib._bootstrap_external>", line 781, in get_code
  File "<frozen importlib._bootstrap_external>", line 741, in source_to_code
  File "<frozen importlib._bootstrap>", line 219, in _call_with_frames_removed
  File "/opt/airflow/dags/mining_etl.py", line 45
    op_kwargs = {'file':"C:\Users\pfaprado\Documents\GitHub\unit-testing\data\processing.csv"},
                       ^
SyntaxError: (unicode error) 'unicodeescape' codec can't decode bytes in position 2-3: truncated \UXXXXXXXX escape
[2023-04-15 23:56:53,326] {processor.py:625} WARNING - No viable dags retrieved from /opt/airflow/dags/mining_etl.py
[2023-04-15 23:56:53,411] {processor.py:170} INFO - Processing /opt/airflow/dags/mining_etl.py took 0.093 seconds
[2023-04-15 23:56:57,771] {processor.py:162} INFO - Started process (PID=280) to work on /opt/airflow/dags/mining_etl.py
[2023-04-15 23:56:57,793] {processor.py:613} INFO - Processing file /opt/airflow/dags/mining_etl.py for tasks to queue
[2023-04-15 23:56:57,794] {logging_mixin.py:109} INFO - [2023-04-15 23:56:57,794] {dagbag.py:496} INFO - Filling up the DagBag from /opt/airflow/dags/mining_etl.py
[2023-04-15 23:56:57,797] {logging_mixin.py:109} INFO - [2023-04-15 23:56:57,796] {dagbag.py:329} ERROR - Failed to import: /opt/airflow/dags/mining_etl.py
Traceback (most recent call last):
  File "/home/airflow/.local/lib/python3.6/site-packages/airflow/models/dagbag.py", line 326, in _load_modules_from_file
    loader.exec_module(new_module)
  File "<frozen importlib._bootstrap_external>", line 674, in exec_module
  File "<frozen importlib._bootstrap_external>", line 781, in get_code
  File "<frozen importlib._bootstrap_external>", line 741, in source_to_code
  File "<frozen importlib._bootstrap>", line 219, in _call_with_frames_removed
  File "/opt/airflow/dags/mining_etl.py", line 45
    op_kwargs = {'file':"C:\Users\pfaprado\Documents\GitHub\unit-testing\data\processing.csv"},
                       ^
SyntaxError: (unicode error) 'unicodeescape' codec can't decode bytes in position 2-3: truncated \UXXXXXXXX escape
[2023-04-15 23:56:57,797] {processor.py:625} WARNING - No viable dags retrieved from /opt/airflow/dags/mining_etl.py
[2023-04-15 23:56:57,838] {processor.py:170} INFO - Processing /opt/airflow/dags/mining_etl.py took 0.071 seconds
[2023-04-15 23:57:27,891] {processor.py:162} INFO - Started process (PID=281) to work on /opt/airflow/dags/mining_etl.py
[2023-04-15 23:57:27,895] {processor.py:613} INFO - Processing file /opt/airflow/dags/mining_etl.py for tasks to queue
[2023-04-15 23:57:27,896] {logging_mixin.py:109} INFO - [2023-04-15 23:57:27,896] {dagbag.py:496} INFO - Filling up the DagBag from /opt/airflow/dags/mining_etl.py
[2023-04-15 23:57:27,901] {logging_mixin.py:109} INFO - [2023-04-15 23:57:27,899] {dagbag.py:329} ERROR - Failed to import: /opt/airflow/dags/mining_etl.py
Traceback (most recent call last):
  File "/home/airflow/.local/lib/python3.6/site-packages/airflow/models/dagbag.py", line 326, in _load_modules_from_file
    loader.exec_module(new_module)
  File "<frozen importlib._bootstrap_external>", line 674, in exec_module
  File "<frozen importlib._bootstrap_external>", line 781, in get_code
  File "<frozen importlib._bootstrap_external>", line 741, in source_to_code
  File "<frozen importlib._bootstrap>", line 219, in _call_with_frames_removed
  File "/opt/airflow/dags/mining_etl.py", line 45
    op_kwargs = {'file':"C:\Users\pfaprado\Documents\GitHub\unit-testing\data\processing.csv"},
                       ^
SyntaxError: (unicode error) 'unicodeescape' codec can't decode bytes in position 2-3: truncated \UXXXXXXXX escape
[2023-04-15 23:57:27,902] {processor.py:625} WARNING - No viable dags retrieved from /opt/airflow/dags/mining_etl.py
[2023-04-15 23:57:27,941] {processor.py:170} INFO - Processing /opt/airflow/dags/mining_etl.py took 0.056 seconds
[2023-04-15 23:57:58,035] {processor.py:162} INFO - Started process (PID=282) to work on /opt/airflow/dags/mining_etl.py
[2023-04-15 23:57:58,038] {processor.py:613} INFO - Processing file /opt/airflow/dags/mining_etl.py for tasks to queue
[2023-04-15 23:57:58,040] {logging_mixin.py:109} INFO - [2023-04-15 23:57:58,039] {dagbag.py:496} INFO - Filling up the DagBag from /opt/airflow/dags/mining_etl.py
[2023-04-15 23:57:58,043] {logging_mixin.py:109} INFO - [2023-04-15 23:57:58,042] {dagbag.py:329} ERROR - Failed to import: /opt/airflow/dags/mining_etl.py
Traceback (most recent call last):
  File "/home/airflow/.local/lib/python3.6/site-packages/airflow/models/dagbag.py", line 326, in _load_modules_from_file
    loader.exec_module(new_module)
  File "<frozen importlib._bootstrap_external>", line 674, in exec_module
  File "<frozen importlib._bootstrap_external>", line 781, in get_code
  File "<frozen importlib._bootstrap_external>", line 741, in source_to_code
  File "<frozen importlib._bootstrap>", line 219, in _call_with_frames_removed
  File "/opt/airflow/dags/mining_etl.py", line 45
    op_kwargs = {'file':"C:\Users\pfaprado\Documents\GitHub\unit-testing\data\processing.csv"},
                       ^
SyntaxError: (unicode error) 'unicodeescape' codec can't decode bytes in position 2-3: truncated \UXXXXXXXX escape
[2023-04-15 23:57:58,043] {processor.py:625} WARNING - No viable dags retrieved from /opt/airflow/dags/mining_etl.py
[2023-04-15 23:57:58,141] {processor.py:170} INFO - Processing /opt/airflow/dags/mining_etl.py took 0.110 seconds
[2023-04-15 23:58:11,200] {processor.py:162} INFO - Started process (PID=283) to work on /opt/airflow/dags/mining_etl.py
[2023-04-15 23:58:11,208] {processor.py:613} INFO - Processing file /opt/airflow/dags/mining_etl.py for tasks to queue
[2023-04-15 23:58:11,211] {logging_mixin.py:109} INFO - [2023-04-15 23:58:11,210] {dagbag.py:496} INFO - Filling up the DagBag from /opt/airflow/dags/mining_etl.py
[2023-04-15 23:58:11,215] {logging_mixin.py:109} INFO - [2023-04-15 23:58:11,214] {dagbag.py:329} ERROR - Failed to import: /opt/airflow/dags/mining_etl.py
Traceback (most recent call last):
  File "/home/airflow/.local/lib/python3.6/site-packages/airflow/models/dagbag.py", line 326, in _load_modules_from_file
    loader.exec_module(new_module)
  File "<frozen importlib._bootstrap_external>", line 674, in exec_module
  File "<frozen importlib._bootstrap_external>", line 781, in get_code
  File "<frozen importlib._bootstrap_external>", line 741, in source_to_code
  File "<frozen importlib._bootstrap>", line 219, in _call_with_frames_removed
  File "/opt/airflow/dags/mining_etl.py", line 45
    op_kwargs = {'file':"C:\Users\pfaprado\Documents\GitHub\unit-testing\data\processing.csv"},
                       ^
SyntaxError: (unicode error) 'unicodeescape' codec can't decode bytes in position 2-3: truncated \UXXXXXXXX escape
[2023-04-15 23:58:11,216] {processor.py:625} WARNING - No viable dags retrieved from /opt/airflow/dags/mining_etl.py
[2023-04-15 23:58:11,266] {processor.py:170} INFO - Processing /opt/airflow/dags/mining_etl.py took 0.080 seconds
[2023-04-15 23:58:21,224] {processor.py:162} INFO - Started process (PID=284) to work on /opt/airflow/dags/mining_etl.py
[2023-04-15 23:58:21,225] {processor.py:613} INFO - Processing file /opt/airflow/dags/mining_etl.py for tasks to queue
[2023-04-15 23:58:21,226] {logging_mixin.py:109} INFO - [2023-04-15 23:58:21,226] {dagbag.py:496} INFO - Filling up the DagBag from /opt/airflow/dags/mining_etl.py
[2023-04-15 23:58:21,228] {logging_mixin.py:109} INFO - [2023-04-15 23:58:21,227] {dagbag.py:329} ERROR - Failed to import: /opt/airflow/dags/mining_etl.py
Traceback (most recent call last):
  File "/home/airflow/.local/lib/python3.6/site-packages/airflow/models/dagbag.py", line 326, in _load_modules_from_file
    loader.exec_module(new_module)
  File "<frozen importlib._bootstrap_external>", line 674, in exec_module
  File "<frozen importlib._bootstrap_external>", line 781, in get_code
  File "<frozen importlib._bootstrap_external>", line 741, in source_to_code
  File "<frozen importlib._bootstrap>", line 219, in _call_with_frames_removed
  File "/opt/airflow/dags/mining_etl.py", line 27
    file.to_csv("C:\Users\pfaprado\Documents\GitHub\unit-testing\data\processing_deliverable.csv", encoding='latin-1')
               ^
SyntaxError: (unicode error) 'unicodeescape' codec can't decode bytes in position 2-3: truncated \UXXXXXXXX escape
[2023-04-15 23:58:21,228] {processor.py:625} WARNING - No viable dags retrieved from /opt/airflow/dags/mining_etl.py
[2023-04-15 23:58:21,307] {processor.py:170} INFO - Processing /opt/airflow/dags/mining_etl.py took 0.086 seconds
[2023-04-15 23:58:32,548] {processor.py:162} INFO - Started process (PID=285) to work on /opt/airflow/dags/mining_etl.py
[2023-04-15 23:58:32,555] {processor.py:613} INFO - Processing file /opt/airflow/dags/mining_etl.py for tasks to queue
[2023-04-15 23:58:32,556] {logging_mixin.py:109} INFO - [2023-04-15 23:58:32,556] {dagbag.py:496} INFO - Filling up the DagBag from /opt/airflow/dags/mining_etl.py
[2023-04-15 23:58:32,559] {logging_mixin.py:109} INFO - [2023-04-15 23:58:32,558] {dagbag.py:329} ERROR - Failed to import: /opt/airflow/dags/mining_etl.py
Traceback (most recent call last):
  File "/home/airflow/.local/lib/python3.6/site-packages/airflow/models/dagbag.py", line 326, in _load_modules_from_file
    loader.exec_module(new_module)
  File "<frozen importlib._bootstrap_external>", line 674, in exec_module
  File "<frozen importlib._bootstrap_external>", line 781, in get_code
  File "<frozen importlib._bootstrap_external>", line 741, in source_to_code
  File "<frozen importlib._bootstrap>", line 219, in _call_with_frames_removed
  File "/opt/airflow/dags/mining_etl.py", line 27
    file.to_csv("C:\Users\pfaprado\Documents\GitHub\unit-testing\data\processing_deliverable.csv", encoding='latin-1')
               ^
SyntaxError: (unicode error) 'unicodeescape' codec can't decode bytes in position 2-3: truncated \UXXXXXXXX escape
[2023-04-15 23:58:32,559] {processor.py:625} WARNING - No viable dags retrieved from /opt/airflow/dags/mining_etl.py
[2023-04-15 23:58:32,599] {processor.py:170} INFO - Processing /opt/airflow/dags/mining_etl.py took 0.054 seconds
[2023-04-15 23:59:02,666] {processor.py:162} INFO - Started process (PID=286) to work on /opt/airflow/dags/mining_etl.py
[2023-04-15 23:59:02,668] {processor.py:613} INFO - Processing file /opt/airflow/dags/mining_etl.py for tasks to queue
[2023-04-15 23:59:02,669] {logging_mixin.py:109} INFO - [2023-04-15 23:59:02,669] {dagbag.py:496} INFO - Filling up the DagBag from /opt/airflow/dags/mining_etl.py
[2023-04-15 23:59:02,674] {logging_mixin.py:109} INFO - [2023-04-15 23:59:02,672] {dagbag.py:329} ERROR - Failed to import: /opt/airflow/dags/mining_etl.py
Traceback (most recent call last):
  File "/home/airflow/.local/lib/python3.6/site-packages/airflow/models/dagbag.py", line 326, in _load_modules_from_file
    loader.exec_module(new_module)
  File "<frozen importlib._bootstrap_external>", line 674, in exec_module
  File "<frozen importlib._bootstrap_external>", line 781, in get_code
  File "<frozen importlib._bootstrap_external>", line 741, in source_to_code
  File "<frozen importlib._bootstrap>", line 219, in _call_with_frames_removed
  File "/opt/airflow/dags/mining_etl.py", line 27
    file.to_csv("C:\Users\pfaprado\Documents\GitHub\unit-testing\data\processing_deliverable.csv", encoding='latin-1')
               ^
SyntaxError: (unicode error) 'unicodeescape' codec can't decode bytes in position 2-3: truncated \UXXXXXXXX escape
[2023-04-15 23:59:02,675] {processor.py:625} WARNING - No viable dags retrieved from /opt/airflow/dags/mining_etl.py
[2023-04-15 23:59:02,720] {processor.py:170} INFO - Processing /opt/airflow/dags/mining_etl.py took 0.060 seconds
[2023-04-15 23:59:32,822] {processor.py:162} INFO - Started process (PID=287) to work on /opt/airflow/dags/mining_etl.py
[2023-04-15 23:59:32,825] {processor.py:613} INFO - Processing file /opt/airflow/dags/mining_etl.py for tasks to queue
[2023-04-15 23:59:32,826] {logging_mixin.py:109} INFO - [2023-04-15 23:59:32,826] {dagbag.py:496} INFO - Filling up the DagBag from /opt/airflow/dags/mining_etl.py
[2023-04-15 23:59:32,831] {logging_mixin.py:109} INFO - [2023-04-15 23:59:32,830] {dagbag.py:329} ERROR - Failed to import: /opt/airflow/dags/mining_etl.py
Traceback (most recent call last):
  File "/home/airflow/.local/lib/python3.6/site-packages/airflow/models/dagbag.py", line 326, in _load_modules_from_file
    loader.exec_module(new_module)
  File "<frozen importlib._bootstrap_external>", line 674, in exec_module
  File "<frozen importlib._bootstrap_external>", line 781, in get_code
  File "<frozen importlib._bootstrap_external>", line 741, in source_to_code
  File "<frozen importlib._bootstrap>", line 219, in _call_with_frames_removed
  File "/opt/airflow/dags/mining_etl.py", line 27
    file.to_csv("C:\Users\pfaprado\Documents\GitHub\unit-testing\data\processing_deliverable.csv", encoding='latin-1')
               ^
SyntaxError: (unicode error) 'unicodeescape' codec can't decode bytes in position 2-3: truncated \UXXXXXXXX escape
[2023-04-15 23:59:32,832] {processor.py:625} WARNING - No viable dags retrieved from /opt/airflow/dags/mining_etl.py
[2023-04-15 23:59:32,882] {processor.py:170} INFO - Processing /opt/airflow/dags/mining_etl.py took 0.068 seconds
