[2023-04-15 23:56:03,114] {taskinstance.py:903} INFO - Dependencies all met for <TaskInstance: processing_dag.processing_task 2023-04-15T23:56:01.543987+00:00 [queued]>
[2023-04-15 23:56:03,152] {taskinstance.py:903} INFO - Dependencies all met for <TaskInstance: processing_dag.processing_task 2023-04-15T23:56:01.543987+00:00 [queued]>
[2023-04-15 23:56:03,153] {taskinstance.py:1095} INFO - 
--------------------------------------------------------------------------------
[2023-04-15 23:56:03,153] {taskinstance.py:1096} INFO - Starting attempt 1 of 1
[2023-04-15 23:56:03,153] {taskinstance.py:1097} INFO - 
--------------------------------------------------------------------------------
[2023-04-15 23:56:03,260] {taskinstance.py:1115} INFO - Executing <Task(PythonOperator): processing_task> on 2023-04-15T23:56:01.543987+00:00
[2023-04-15 23:56:03,268] {standard_task_runner.py:52} INFO - Started process 58 to run task
[2023-04-15 23:56:03,280] {standard_task_runner.py:76} INFO - Running: ['***', 'tasks', 'run', 'processing_dag', 'processing_task', '2023-04-15T23:56:01.543987+00:00', '--job-id', '5', '--pool', 'default_pool', '--raw', '--subdir', 'DAGS_FOLDER/mining_etl.py', '--cfg-path', '/tmp/tmpm4v4wtrq', '--error-file', '/tmp/tmpvz3q3ihr']
[2023-04-15 23:56:03,281] {standard_task_runner.py:77} INFO - Job 5: Subtask processing_task
[2023-04-15 23:56:03,402] {logging_mixin.py:109} INFO - Running <TaskInstance: processing_dag.processing_task 2023-04-15T23:56:01.543987+00:00 [running]> on host d1ce0343a975
[2023-04-15 23:56:03,523] {taskinstance.py:1254} INFO - Exporting the following env vars:
AIRFLOW_CTX_DAG_OWNER=***
AIRFLOW_CTX_DAG_ID=processing_dag
AIRFLOW_CTX_TASK_ID=processing_task
AIRFLOW_CTX_EXECUTION_DATE=2023-04-15T23:56:01.543987+00:00
AIRFLOW_CTX_DAG_RUN_ID=manual__2023-04-15T23:56:01.543987+00:00
[2023-04-15 23:56:03,525] {taskinstance.py:1463} ERROR - Task failed with exception
Traceback (most recent call last):
  File "/home/airflow/.local/lib/python3.6/site-packages/airflow/models/taskinstance.py", line 1165, in _run_raw_task
    self._prepare_and_execute_task_with_callbacks(context, task)
  File "/home/airflow/.local/lib/python3.6/site-packages/airflow/models/taskinstance.py", line 1283, in _prepare_and_execute_task_with_callbacks
    result = self._execute_task(context, task_copy)
  File "/home/airflow/.local/lib/python3.6/site-packages/airflow/models/taskinstance.py", line 1313, in _execute_task
    result = task_copy.execute(context=context)
  File "/home/airflow/.local/lib/python3.6/site-packages/airflow/operators/python.py", line 150, in execute
    return_value = self.execute_callable()
  File "/home/airflow/.local/lib/python3.6/site-packages/airflow/operators/python.py", line 161, in execute_callable
    return self.python_callable(*self.op_args, **self.op_kwargs)
  File "/opt/airflow/dags/mining_etl.py", line 11, in process
    file = pd.read_csv(file)
  File "/home/airflow/.local/lib/python3.6/site-packages/pandas/io/parsers.py", line 688, in read_csv
    return _read(filepath_or_buffer, kwds)
  File "/home/airflow/.local/lib/python3.6/site-packages/pandas/io/parsers.py", line 454, in _read
    parser = TextFileReader(fp_or_buf, **kwds)
  File "/home/airflow/.local/lib/python3.6/site-packages/pandas/io/parsers.py", line 948, in __init__
    self._make_engine(self.engine)
  File "/home/airflow/.local/lib/python3.6/site-packages/pandas/io/parsers.py", line 1180, in _make_engine
    self._engine = CParserWrapper(self.f, **self.options)
  File "/home/airflow/.local/lib/python3.6/site-packages/pandas/io/parsers.py", line 2010, in __init__
    self._reader = parsers.TextReader(src, **kwds)
  File "pandas/_libs/parsers.pyx", line 382, in pandas._libs.parsers.TextReader.__cinit__
  File "pandas/_libs/parsers.pyx", line 674, in pandas._libs.parsers.TextReader._setup_parser_source
FileNotFoundError: [Errno 2] No such file or directory: 'C:\\Users\\pfaprado\\Documents\\GitHub\\unit-testing\\data\\processing.csv'
[2023-04-15 23:56:03,530] {taskinstance.py:1513} INFO - Marking task as FAILED. dag_id=processing_dag, task_id=processing_task, execution_date=20230415T235601, start_date=20230415T235603, end_date=20230415T235603
[2023-04-15 23:56:03,652] {local_task_job.py:151} INFO - Task exited with return code 1
[2023-04-15 23:56:03,713] {local_task_job.py:261} INFO - 0 downstream tasks scheduled from follow-on schedule check
